{
  "nbformat": 4,
  "nbformat_minor": 0,
  "metadata": {
    "colab": {
      "provenance": []
    },
    "kernelspec": {
      "name": "python3",
      "display_name": "Python 3"
    },
    "language_info": {
      "name": "python"
    }
  },
  "cells": [
    {
      "cell_type": "markdown",
      "source": [
        "# 1.) Import an asset price from Yahoo Finance"
      ],
      "metadata": {
        "id": "6dJuZDx9qWeM"
      }
    },
    {
      "cell_type": "code",
      "source": [
        "pip install yfinance"
      ],
      "metadata": {
        "colab": {
          "base_uri": "https://localhost:8080/"
        },
        "id": "QxUUnTVTrx3m",
        "outputId": "3163fc2b-5b45-466b-fefe-0ebe7349a9ed"
      },
      "execution_count": null,
      "outputs": [
        {
          "output_type": "stream",
          "name": "stdout",
          "text": [
            "Looking in indexes: https://pypi.org/simple, https://us-python.pkg.dev/colab-wheels/public/simple/\n",
            "Collecting yfinance\n",
            "  Downloading yfinance-0.2.12-py2.py3-none-any.whl (59 kB)\n",
            "\u001b[2K     \u001b[90m━━━━━━━━━━━━━━━━━━━━━━━━━━━━━━━━━━━━━━━━\u001b[0m \u001b[32m59.2/59.2 KB\u001b[0m \u001b[31m1.8 MB/s\u001b[0m eta \u001b[36m0:00:00\u001b[0m\n",
            "\u001b[?25hRequirement already satisfied: appdirs>=1.4.4 in /usr/local/lib/python3.8/dist-packages (from yfinance) (1.4.4)\n",
            "Requirement already satisfied: pandas>=1.3.0 in /usr/local/lib/python3.8/dist-packages (from yfinance) (1.3.5)\n",
            "Collecting html5lib>=1.1\n",
            "  Downloading html5lib-1.1-py2.py3-none-any.whl (112 kB)\n",
            "\u001b[2K     \u001b[90m━━━━━━━━━━━━━━━━━━━━━━━━━━━━━━━━━━━━━━━\u001b[0m \u001b[32m112.2/112.2 KB\u001b[0m \u001b[31m5.5 MB/s\u001b[0m eta \u001b[36m0:00:00\u001b[0m\n",
            "\u001b[?25hCollecting frozendict>=2.3.4\n",
            "  Downloading frozendict-2.3.5-cp38-cp38-manylinux_2_17_x86_64.manylinux2014_x86_64.whl (111 kB)\n",
            "\u001b[2K     \u001b[90m━━━━━━━━━━━━━━━━━━━━━━━━━━━━━━━━━━━━━━━\u001b[0m \u001b[32m111.2/111.2 KB\u001b[0m \u001b[31m4.9 MB/s\u001b[0m eta \u001b[36m0:00:00\u001b[0m\n",
            "\u001b[?25hCollecting cryptography>=3.3.2\n",
            "  Downloading cryptography-39.0.1-cp36-abi3-manylinux_2_28_x86_64.whl (4.2 MB)\n",
            "\u001b[2K     \u001b[90m━━━━━━━━━━━━━━━━━━━━━━━━━━━━━━━━━━━━━━━━\u001b[0m \u001b[32m4.2/4.2 MB\u001b[0m \u001b[31m22.6 MB/s\u001b[0m eta \u001b[36m0:00:00\u001b[0m\n",
            "\u001b[?25hCollecting requests>=2.26\n",
            "  Downloading requests-2.28.2-py3-none-any.whl (62 kB)\n",
            "\u001b[2K     \u001b[90m━━━━━━━━━━━━━━━━━━━━━━━━━━━━━━━━━━━━━━━━\u001b[0m \u001b[32m62.8/62.8 KB\u001b[0m \u001b[31m2.7 MB/s\u001b[0m eta \u001b[36m0:00:00\u001b[0m\n",
            "\u001b[?25hCollecting beautifulsoup4>=4.11.1\n",
            "  Downloading beautifulsoup4-4.11.2-py3-none-any.whl (129 kB)\n",
            "\u001b[2K     \u001b[90m━━━━━━━━━━━━━━━━━━━━━━━━━━━━━━━━━━━━━━━\u001b[0m \u001b[32m129.4/129.4 KB\u001b[0m \u001b[31m7.1 MB/s\u001b[0m eta \u001b[36m0:00:00\u001b[0m\n",
            "\u001b[?25hRequirement already satisfied: lxml>=4.9.1 in /usr/local/lib/python3.8/dist-packages (from yfinance) (4.9.2)\n",
            "Requirement already satisfied: pytz>=2022.5 in /usr/local/lib/python3.8/dist-packages (from yfinance) (2022.7.1)\n",
            "Requirement already satisfied: multitasking>=0.0.7 in /usr/local/lib/python3.8/dist-packages (from yfinance) (0.0.11)\n",
            "Requirement already satisfied: numpy>=1.16.5 in /usr/local/lib/python3.8/dist-packages (from yfinance) (1.22.4)\n",
            "Collecting soupsieve>1.2\n",
            "  Downloading soupsieve-2.4-py3-none-any.whl (37 kB)\n",
            "Requirement already satisfied: cffi>=1.12 in /usr/local/lib/python3.8/dist-packages (from cryptography>=3.3.2->yfinance) (1.15.1)\n",
            "Requirement already satisfied: webencodings in /usr/local/lib/python3.8/dist-packages (from html5lib>=1.1->yfinance) (0.5.1)\n",
            "Requirement already satisfied: six>=1.9 in /usr/local/lib/python3.8/dist-packages (from html5lib>=1.1->yfinance) (1.15.0)\n",
            "Requirement already satisfied: python-dateutil>=2.7.3 in /usr/local/lib/python3.8/dist-packages (from pandas>=1.3.0->yfinance) (2.8.2)\n",
            "Requirement already satisfied: charset-normalizer<4,>=2 in /usr/local/lib/python3.8/dist-packages (from requests>=2.26->yfinance) (3.0.1)\n",
            "Requirement already satisfied: urllib3<1.27,>=1.21.1 in /usr/local/lib/python3.8/dist-packages (from requests>=2.26->yfinance) (1.24.3)\n",
            "Requirement already satisfied: certifi>=2017.4.17 in /usr/local/lib/python3.8/dist-packages (from requests>=2.26->yfinance) (2022.12.7)\n",
            "Requirement already satisfied: idna<4,>=2.5 in /usr/local/lib/python3.8/dist-packages (from requests>=2.26->yfinance) (2.10)\n",
            "Requirement already satisfied: pycparser in /usr/local/lib/python3.8/dist-packages (from cffi>=1.12->cryptography>=3.3.2->yfinance) (2.21)\n",
            "Installing collected packages: soupsieve, requests, html5lib, frozendict, cryptography, beautifulsoup4, yfinance\n",
            "  Attempting uninstall: requests\n",
            "    Found existing installation: requests 2.25.1\n",
            "    Uninstalling requests-2.25.1:\n",
            "      Successfully uninstalled requests-2.25.1\n",
            "  Attempting uninstall: html5lib\n",
            "    Found existing installation: html5lib 1.0.1\n",
            "    Uninstalling html5lib-1.0.1:\n",
            "      Successfully uninstalled html5lib-1.0.1\n",
            "  Attempting uninstall: beautifulsoup4\n",
            "    Found existing installation: beautifulsoup4 4.6.3\n",
            "    Uninstalling beautifulsoup4-4.6.3:\n",
            "      Successfully uninstalled beautifulsoup4-4.6.3\n",
            "Successfully installed beautifulsoup4-4.11.2 cryptography-39.0.1 frozendict-2.3.5 html5lib-1.1 requests-2.28.2 soupsieve-2.4 yfinance-0.2.12\n"
          ]
        }
      ]
    },
    {
      "cell_type": "code",
      "source": [
        "import yfinance as yf\n",
        "import numpy as np\n",
        "import pandas as pd\n",
        "from sklearn.preprocessing import MinMaxScaler\n",
        "from tensorflow.keras.models import Sequential\n",
        "from tensorflow.keras.layers import Dense, LSTM, Dropout"
      ],
      "metadata": {
        "id": "IomjgONAwjqD"
      },
      "execution_count": null,
      "outputs": []
    },
    {
      "cell_type": "code",
      "source": [
        "########################################\n",
        "####Pick your ticker and time period####\n",
        "########################################\n",
        "stock_data = yf.download(\"MSFT\", start=\"1990-01-01\", end=\"2022-02-21\")"
      ],
      "metadata": {
        "colab": {
          "base_uri": "https://localhost:8080/"
        },
        "id": "OPm8dSzmwt2s",
        "outputId": "ac380dd5-5950-4104-c161-6d5bea18c9d0"
      },
      "execution_count": null,
      "outputs": [
        {
          "output_type": "stream",
          "name": "stdout",
          "text": [
            "\r[*********************100%***********************]  1 of 1 completed\n"
          ]
        }
      ]
    },
    {
      "cell_type": "code",
      "source": [
        "stock_data"
      ],
      "metadata": {
        "colab": {
          "base_uri": "https://localhost:8080/",
          "height": 455
        },
        "id": "CrOE57gcwyrl",
        "outputId": "d23a4af7-8222-40f5-fb8e-3a0e63586ae8"
      },
      "execution_count": null,
      "outputs": [
        {
          "output_type": "execute_result",
          "data": {
            "text/plain": [
              "                  Open        High         Low       Close   Adj Close  \\\n",
              "Date                                                                     \n",
              "1990-01-02    0.605903    0.616319    0.598090    0.616319    0.384520   \n",
              "1990-01-03    0.621528    0.626736    0.614583    0.619792    0.386687   \n",
              "1990-01-04    0.619792    0.638889    0.616319    0.638021    0.398060   \n",
              "1990-01-05    0.635417    0.638889    0.621528    0.622396    0.388312   \n",
              "1990-01-08    0.621528    0.631944    0.614583    0.631944    0.394269   \n",
              "...                ...         ...         ...         ...         ...   \n",
              "2022-02-14  293.769989  296.760010  291.350006  295.000000  291.531281   \n",
              "2022-02-15  300.010010  300.799988  297.019989  300.470001  296.936951   \n",
              "2022-02-16  298.369995  300.869995  293.679993  299.500000  296.590363   \n",
              "2022-02-17  296.359985  296.799988  290.000000  290.730011  287.905548   \n",
              "2022-02-18  293.049988  293.859985  286.309998  287.929993  285.132721   \n",
              "\n",
              "               Volume  \n",
              "Date                   \n",
              "1990-01-02   53035200  \n",
              "1990-01-03  113774400  \n",
              "1990-01-04  125740800  \n",
              "1990-01-05   69566400  \n",
              "1990-01-08   58982400  \n",
              "...               ...  \n",
              "2022-02-14   36359500  \n",
              "2022-02-15   27058300  \n",
              "2022-02-16   29982100  \n",
              "2022-02-17   32461600  \n",
              "2022-02-18   34264000  \n",
              "\n",
              "[8098 rows x 6 columns]"
            ],
            "text/html": [
              "\n",
              "  <div id=\"df-647a03e5-935f-4c0c-a2d4-4d90a5f83327\">\n",
              "    <div class=\"colab-df-container\">\n",
              "      <div>\n",
              "<style scoped>\n",
              "    .dataframe tbody tr th:only-of-type {\n",
              "        vertical-align: middle;\n",
              "    }\n",
              "\n",
              "    .dataframe tbody tr th {\n",
              "        vertical-align: top;\n",
              "    }\n",
              "\n",
              "    .dataframe thead th {\n",
              "        text-align: right;\n",
              "    }\n",
              "</style>\n",
              "<table border=\"1\" class=\"dataframe\">\n",
              "  <thead>\n",
              "    <tr style=\"text-align: right;\">\n",
              "      <th></th>\n",
              "      <th>Open</th>\n",
              "      <th>High</th>\n",
              "      <th>Low</th>\n",
              "      <th>Close</th>\n",
              "      <th>Adj Close</th>\n",
              "      <th>Volume</th>\n",
              "    </tr>\n",
              "    <tr>\n",
              "      <th>Date</th>\n",
              "      <th></th>\n",
              "      <th></th>\n",
              "      <th></th>\n",
              "      <th></th>\n",
              "      <th></th>\n",
              "      <th></th>\n",
              "    </tr>\n",
              "  </thead>\n",
              "  <tbody>\n",
              "    <tr>\n",
              "      <th>1990-01-02</th>\n",
              "      <td>0.605903</td>\n",
              "      <td>0.616319</td>\n",
              "      <td>0.598090</td>\n",
              "      <td>0.616319</td>\n",
              "      <td>0.384520</td>\n",
              "      <td>53035200</td>\n",
              "    </tr>\n",
              "    <tr>\n",
              "      <th>1990-01-03</th>\n",
              "      <td>0.621528</td>\n",
              "      <td>0.626736</td>\n",
              "      <td>0.614583</td>\n",
              "      <td>0.619792</td>\n",
              "      <td>0.386687</td>\n",
              "      <td>113774400</td>\n",
              "    </tr>\n",
              "    <tr>\n",
              "      <th>1990-01-04</th>\n",
              "      <td>0.619792</td>\n",
              "      <td>0.638889</td>\n",
              "      <td>0.616319</td>\n",
              "      <td>0.638021</td>\n",
              "      <td>0.398060</td>\n",
              "      <td>125740800</td>\n",
              "    </tr>\n",
              "    <tr>\n",
              "      <th>1990-01-05</th>\n",
              "      <td>0.635417</td>\n",
              "      <td>0.638889</td>\n",
              "      <td>0.621528</td>\n",
              "      <td>0.622396</td>\n",
              "      <td>0.388312</td>\n",
              "      <td>69566400</td>\n",
              "    </tr>\n",
              "    <tr>\n",
              "      <th>1990-01-08</th>\n",
              "      <td>0.621528</td>\n",
              "      <td>0.631944</td>\n",
              "      <td>0.614583</td>\n",
              "      <td>0.631944</td>\n",
              "      <td>0.394269</td>\n",
              "      <td>58982400</td>\n",
              "    </tr>\n",
              "    <tr>\n",
              "      <th>...</th>\n",
              "      <td>...</td>\n",
              "      <td>...</td>\n",
              "      <td>...</td>\n",
              "      <td>...</td>\n",
              "      <td>...</td>\n",
              "      <td>...</td>\n",
              "    </tr>\n",
              "    <tr>\n",
              "      <th>2022-02-14</th>\n",
              "      <td>293.769989</td>\n",
              "      <td>296.760010</td>\n",
              "      <td>291.350006</td>\n",
              "      <td>295.000000</td>\n",
              "      <td>291.531281</td>\n",
              "      <td>36359500</td>\n",
              "    </tr>\n",
              "    <tr>\n",
              "      <th>2022-02-15</th>\n",
              "      <td>300.010010</td>\n",
              "      <td>300.799988</td>\n",
              "      <td>297.019989</td>\n",
              "      <td>300.470001</td>\n",
              "      <td>296.936951</td>\n",
              "      <td>27058300</td>\n",
              "    </tr>\n",
              "    <tr>\n",
              "      <th>2022-02-16</th>\n",
              "      <td>298.369995</td>\n",
              "      <td>300.869995</td>\n",
              "      <td>293.679993</td>\n",
              "      <td>299.500000</td>\n",
              "      <td>296.590363</td>\n",
              "      <td>29982100</td>\n",
              "    </tr>\n",
              "    <tr>\n",
              "      <th>2022-02-17</th>\n",
              "      <td>296.359985</td>\n",
              "      <td>296.799988</td>\n",
              "      <td>290.000000</td>\n",
              "      <td>290.730011</td>\n",
              "      <td>287.905548</td>\n",
              "      <td>32461600</td>\n",
              "    </tr>\n",
              "    <tr>\n",
              "      <th>2022-02-18</th>\n",
              "      <td>293.049988</td>\n",
              "      <td>293.859985</td>\n",
              "      <td>286.309998</td>\n",
              "      <td>287.929993</td>\n",
              "      <td>285.132721</td>\n",
              "      <td>34264000</td>\n",
              "    </tr>\n",
              "  </tbody>\n",
              "</table>\n",
              "<p>8098 rows × 6 columns</p>\n",
              "</div>\n",
              "      <button class=\"colab-df-convert\" onclick=\"convertToInteractive('df-647a03e5-935f-4c0c-a2d4-4d90a5f83327')\"\n",
              "              title=\"Convert this dataframe to an interactive table.\"\n",
              "              style=\"display:none;\">\n",
              "        \n",
              "  <svg xmlns=\"http://www.w3.org/2000/svg\" height=\"24px\"viewBox=\"0 0 24 24\"\n",
              "       width=\"24px\">\n",
              "    <path d=\"M0 0h24v24H0V0z\" fill=\"none\"/>\n",
              "    <path d=\"M18.56 5.44l.94 2.06.94-2.06 2.06-.94-2.06-.94-.94-2.06-.94 2.06-2.06.94zm-11 1L8.5 8.5l.94-2.06 2.06-.94-2.06-.94L8.5 2.5l-.94 2.06-2.06.94zm10 10l.94 2.06.94-2.06 2.06-.94-2.06-.94-.94-2.06-.94 2.06-2.06.94z\"/><path d=\"M17.41 7.96l-1.37-1.37c-.4-.4-.92-.59-1.43-.59-.52 0-1.04.2-1.43.59L10.3 9.45l-7.72 7.72c-.78.78-.78 2.05 0 2.83L4 21.41c.39.39.9.59 1.41.59.51 0 1.02-.2 1.41-.59l7.78-7.78 2.81-2.81c.8-.78.8-2.07 0-2.86zM5.41 20L4 18.59l7.72-7.72 1.47 1.35L5.41 20z\"/>\n",
              "  </svg>\n",
              "      </button>\n",
              "      \n",
              "  <style>\n",
              "    .colab-df-container {\n",
              "      display:flex;\n",
              "      flex-wrap:wrap;\n",
              "      gap: 12px;\n",
              "    }\n",
              "\n",
              "    .colab-df-convert {\n",
              "      background-color: #E8F0FE;\n",
              "      border: none;\n",
              "      border-radius: 50%;\n",
              "      cursor: pointer;\n",
              "      display: none;\n",
              "      fill: #1967D2;\n",
              "      height: 32px;\n",
              "      padding: 0 0 0 0;\n",
              "      width: 32px;\n",
              "    }\n",
              "\n",
              "    .colab-df-convert:hover {\n",
              "      background-color: #E2EBFA;\n",
              "      box-shadow: 0px 1px 2px rgba(60, 64, 67, 0.3), 0px 1px 3px 1px rgba(60, 64, 67, 0.15);\n",
              "      fill: #174EA6;\n",
              "    }\n",
              "\n",
              "    [theme=dark] .colab-df-convert {\n",
              "      background-color: #3B4455;\n",
              "      fill: #D2E3FC;\n",
              "    }\n",
              "\n",
              "    [theme=dark] .colab-df-convert:hover {\n",
              "      background-color: #434B5C;\n",
              "      box-shadow: 0px 1px 3px 1px rgba(0, 0, 0, 0.15);\n",
              "      filter: drop-shadow(0px 1px 2px rgba(0, 0, 0, 0.3));\n",
              "      fill: #FFFFFF;\n",
              "    }\n",
              "  </style>\n",
              "\n",
              "      <script>\n",
              "        const buttonEl =\n",
              "          document.querySelector('#df-647a03e5-935f-4c0c-a2d4-4d90a5f83327 button.colab-df-convert');\n",
              "        buttonEl.style.display =\n",
              "          google.colab.kernel.accessAllowed ? 'block' : 'none';\n",
              "\n",
              "        async function convertToInteractive(key) {\n",
              "          const element = document.querySelector('#df-647a03e5-935f-4c0c-a2d4-4d90a5f83327');\n",
              "          const dataTable =\n",
              "            await google.colab.kernel.invokeFunction('convertToInteractive',\n",
              "                                                     [key], {});\n",
              "          if (!dataTable) return;\n",
              "\n",
              "          const docLinkHtml = 'Like what you see? Visit the ' +\n",
              "            '<a target=\"_blank\" href=https://colab.research.google.com/notebooks/data_table.ipynb>data table notebook</a>'\n",
              "            + ' to learn more about interactive tables.';\n",
              "          element.innerHTML = '';\n",
              "          dataTable['output_type'] = 'display_data';\n",
              "          await google.colab.output.renderOutput(dataTable, element);\n",
              "          const docLink = document.createElement('div');\n",
              "          docLink.innerHTML = docLinkHtml;\n",
              "          element.appendChild(docLink);\n",
              "        }\n",
              "      </script>\n",
              "    </div>\n",
              "  </div>\n",
              "  "
            ]
          },
          "metadata": {},
          "execution_count": 4
        }
      ]
    },
    {
      "cell_type": "code",
      "source": [
        "scaled_data = np.array(stock_data[\"Close\"].pct_change().dropna()).reshape(-1,1)"
      ],
      "metadata": {
        "id": "s-2qagu5xEBr"
      },
      "execution_count": null,
      "outputs": []
    },
    {
      "cell_type": "code",
      "source": [
        "scaled_data"
      ],
      "metadata": {
        "colab": {
          "base_uri": "https://localhost:8080/"
        },
        "id": "wOM7YuAsyYW9",
        "outputId": "e8616639-8d05-4cf3-ac89-07ef8fb9f927"
      },
      "execution_count": null,
      "outputs": [
        {
          "output_type": "execute_result",
          "data": {
            "text/plain": [
              "array([[ 0.00563504],\n",
              "       [ 0.02941149],\n",
              "       [-0.02448979],\n",
              "       ...,\n",
              "       [-0.00322828],\n",
              "       [-0.0292821 ],\n",
              "       [-0.00963099]])"
            ]
          },
          "metadata": {},
          "execution_count": 7
        }
      ]
    },
    {
      "cell_type": "code",
      "execution_count": null,
      "metadata": {
        "id": "Y3bcwJb4rp93"
      },
      "outputs": [],
      "source": [
        "# Split data into training and test sets\n",
        "training_data_len = int(len(scaled_data) * 0.8)\n",
        "train_data = scaled_data[0:training_data_len, :]\n",
        "\n"
      ]
    },
    {
      "cell_type": "code",
      "source": [
        "training_data_len"
      ],
      "metadata": {
        "colab": {
          "base_uri": "https://localhost:8080/"
        },
        "id": "B_LubdU-yeCL",
        "outputId": "588cfbc8-2d49-411a-d6d5-2c6549a1169f"
      },
      "execution_count": null,
      "outputs": [
        {
          "output_type": "execute_result",
          "data": {
            "text/plain": [
              "6477"
            ]
          },
          "metadata": {},
          "execution_count": 8
        }
      ]
    },
    {
      "cell_type": "code",
      "source": [
        "train_data"
      ],
      "metadata": {
        "colab": {
          "base_uri": "https://localhost:8080/"
        },
        "id": "mz5-HAuUyieB",
        "outputId": "aabd7212-cd79-4057-d9b8-80540a768d16"
      },
      "execution_count": null,
      "outputs": [
        {
          "output_type": "execute_result",
          "data": {
            "text/plain": [
              "array([[ 0.00563504],\n",
              "       [ 0.02941149],\n",
              "       [-0.02448979],\n",
              "       ...,\n",
              "       [ 0.00438897],\n",
              "       [-0.01011956],\n",
              "       [ 0.02184012]])"
            ]
          },
          "metadata": {},
          "execution_count": 9
        }
      ]
    },
    {
      "cell_type": "markdown",
      "source": [
        "# 2.) Create your x_train/y_train data so that your RNN uses percentage change data to make a binary forecast where the stock moves up or down the next day\n",
        "# Build an RNN Architecture accordingly"
      ],
      "metadata": {
        "id": "foHoGy9hq3_o"
      }
    },
    {
      "cell_type": "code",
      "source": [
        "x_train = []\n",
        "y_train = []\n",
        "\n",
        "#############################################################\n",
        "####Pick your input size and edit to make binary forecast####\n",
        "#############################################################\n",
        "\n",
        "#forecasting here did the stock price move up or down tomorrow\n",
        "    # instead of having y_train be a percentage dif it shud just be did stock move up or down\n",
        "\n",
        "# input size = this is the number of time lags, 2 = today and yesterdays price data to forecast tomorrow\n",
        "input_size = 10\n",
        "for i in range(input_size, len(train_data)):\n",
        "    x_train.append(train_data[i-input_size:i, 0])\n",
        "    if train_data[i, 0] > train_data[i-1, 0]:\n",
        "        y_train.append(1)  # stock moved up\n",
        "    else:\n",
        "        y_train.append(0)  \n",
        "        \n",
        "x_train, y_train = np.array(x_train), np.array(y_train)\n",
        "# Reshape x_train to match input shape of LSTM layer\n",
        "x_train = np.reshape(x_train, (x_train.shape[0], x_train.shape[1], 1))"
      ],
      "metadata": {
        "id": "uzDKBV2G33i4"
      },
      "execution_count": null,
      "outputs": []
    },
    {
      "cell_type": "markdown",
      "source": [
        "Now, we can build our RNN architecture using the Sequential model from Keras. We will use an LSTM layer with 50 units, followed by a dropout layer to prevent overfitting. Finally, we will add a dense layer with one unit and a sigmoid activation function to make the binary prediction."
      ],
      "metadata": {
        "id": "LkGgOWsE4JqI"
      }
    },
    {
      "cell_type": "code",
      "source": [
        "model = Sequential()\n",
        "\n",
        "model.add(LSTM(50, return_sequences=True, input_shape=(x_train.shape[1], 1)))\n",
        "model.add(Dropout(0.2))\n",
        "model.add(LSTM(50))\n",
        "model.add(Dropout(0.2))\n",
        "model.add(Dense(1, activation='sigmoid'))\n",
        "model.compile(optimizer='adam', loss='binary_crossentropy', metrics=['accuracy'])"
      ],
      "metadata": {
        "id": "gwR9pWlO4Gna"
      },
      "execution_count": null,
      "outputs": []
    },
    {
      "cell_type": "code",
      "source": [
        "model.fit(x_train, y_train, epochs=50, batch_size=32)"
      ],
      "metadata": {
        "colab": {
          "base_uri": "https://localhost:8080/"
        },
        "id": "EUZg6j7_4U4r",
        "outputId": "726f0ce2-20fd-4333-9f36-21a2d01d8c93"
      },
      "execution_count": null,
      "outputs": [
        {
          "output_type": "stream",
          "name": "stdout",
          "text": [
            "Epoch 1/50\n",
            "203/203 [==============================] - 9s 15ms/step - loss: 0.6930 - accuracy: 0.5123\n",
            "Epoch 2/50\n",
            "203/203 [==============================] - 3s 15ms/step - loss: 0.6921 - accuracy: 0.5234\n",
            "Epoch 3/50\n",
            "203/203 [==============================] - 3s 17ms/step - loss: 0.6801 - accuracy: 0.5783\n",
            "Epoch 4/50\n",
            "203/203 [==============================] - 4s 21ms/step - loss: 0.6144 - accuracy: 0.6657\n",
            "Epoch 5/50\n",
            "203/203 [==============================] - 3s 15ms/step - loss: 0.5633 - accuracy: 0.7088\n",
            "Epoch 6/50\n",
            "203/203 [==============================] - 3s 15ms/step - loss: 0.5414 - accuracy: 0.7291\n",
            "Epoch 7/50\n",
            "203/203 [==============================] - 3s 16ms/step - loss: 0.5343 - accuracy: 0.7385\n",
            "Epoch 8/50\n",
            "203/203 [==============================] - 4s 20ms/step - loss: 0.5316 - accuracy: 0.7385\n",
            "Epoch 9/50\n",
            "203/203 [==============================] - 3s 15ms/step - loss: 0.5288 - accuracy: 0.7421\n",
            "Epoch 10/50\n",
            "203/203 [==============================] - 3s 15ms/step - loss: 0.5260 - accuracy: 0.7402\n",
            "Epoch 11/50\n",
            "203/203 [==============================] - 3s 16ms/step - loss: 0.5278 - accuracy: 0.7381\n",
            "Epoch 12/50\n",
            "203/203 [==============================] - 4s 20ms/step - loss: 0.5258 - accuracy: 0.7467\n",
            "Epoch 13/50\n",
            "203/203 [==============================] - 3s 15ms/step - loss: 0.5226 - accuracy: 0.7478\n",
            "Epoch 14/50\n",
            "203/203 [==============================] - 4s 20ms/step - loss: 0.5231 - accuracy: 0.7404\n",
            "Epoch 15/50\n",
            "203/203 [==============================] - 4s 20ms/step - loss: 0.5204 - accuracy: 0.7452\n",
            "Epoch 16/50\n",
            "203/203 [==============================] - 3s 16ms/step - loss: 0.5218 - accuracy: 0.7450\n",
            "Epoch 17/50\n",
            "203/203 [==============================] - 3s 15ms/step - loss: 0.5205 - accuracy: 0.7445\n",
            "Epoch 18/50\n",
            "203/203 [==============================] - 3s 16ms/step - loss: 0.5230 - accuracy: 0.7430\n",
            "Epoch 19/50\n",
            "203/203 [==============================] - 4s 21ms/step - loss: 0.5197 - accuracy: 0.7439\n",
            "Epoch 20/50\n",
            "203/203 [==============================] - 3s 16ms/step - loss: 0.5181 - accuracy: 0.7458\n",
            "Epoch 21/50\n",
            "203/203 [==============================] - 3s 16ms/step - loss: 0.5188 - accuracy: 0.7439\n",
            "Epoch 22/50\n",
            "203/203 [==============================] - 3s 15ms/step - loss: 0.5211 - accuracy: 0.7449\n",
            "Epoch 23/50\n",
            "203/203 [==============================] - 4s 21ms/step - loss: 0.5203 - accuracy: 0.7463\n",
            "Epoch 24/50\n",
            "203/203 [==============================] - 3s 16ms/step - loss: 0.5183 - accuracy: 0.7475\n",
            "Epoch 25/50\n",
            "203/203 [==============================] - 3s 15ms/step - loss: 0.5178 - accuracy: 0.7487\n",
            "Epoch 26/50\n",
            "203/203 [==============================] - 3s 16ms/step - loss: 0.5195 - accuracy: 0.7421\n",
            "Epoch 27/50\n",
            "203/203 [==============================] - 4s 21ms/step - loss: 0.5175 - accuracy: 0.7461\n",
            "Epoch 28/50\n",
            "203/203 [==============================] - 3s 15ms/step - loss: 0.5175 - accuracy: 0.7493\n",
            "Epoch 29/50\n",
            "203/203 [==============================] - 3s 15ms/step - loss: 0.5161 - accuracy: 0.7455\n",
            "Epoch 30/50\n",
            "203/203 [==============================] - 3s 17ms/step - loss: 0.5158 - accuracy: 0.7466\n",
            "Epoch 31/50\n",
            "203/203 [==============================] - 4s 20ms/step - loss: 0.5149 - accuracy: 0.7441\n",
            "Epoch 32/50\n",
            "203/203 [==============================] - 3s 15ms/step - loss: 0.5150 - accuracy: 0.7444\n",
            "Epoch 33/50\n",
            "203/203 [==============================] - 3s 16ms/step - loss: 0.5152 - accuracy: 0.7469\n",
            "Epoch 34/50\n",
            "203/203 [==============================] - 4s 18ms/step - loss: 0.5139 - accuracy: 0.7453\n",
            "Epoch 35/50\n",
            "203/203 [==============================] - 4s 19ms/step - loss: 0.5112 - accuracy: 0.7500\n",
            "Epoch 36/50\n",
            "203/203 [==============================] - 3s 16ms/step - loss: 0.5143 - accuracy: 0.7478\n",
            "Epoch 37/50\n",
            "203/203 [==============================] - 3s 15ms/step - loss: 0.5135 - accuracy: 0.7461\n",
            "Epoch 38/50\n",
            "203/203 [==============================] - 4s 19ms/step - loss: 0.5105 - accuracy: 0.7472\n",
            "Epoch 39/50\n",
            "203/203 [==============================] - 4s 17ms/step - loss: 0.5133 - accuracy: 0.7515\n",
            "Epoch 40/50\n",
            "203/203 [==============================] - 3s 16ms/step - loss: 0.5131 - accuracy: 0.7486\n",
            "Epoch 41/50\n",
            "203/203 [==============================] - 3s 15ms/step - loss: 0.5099 - accuracy: 0.7526\n",
            "Epoch 42/50\n",
            "203/203 [==============================] - 4s 21ms/step - loss: 0.5119 - accuracy: 0.7492\n",
            "Epoch 43/50\n",
            "203/203 [==============================] - 3s 16ms/step - loss: 0.5130 - accuracy: 0.7453\n",
            "Epoch 44/50\n",
            "203/203 [==============================] - 3s 16ms/step - loss: 0.5084 - accuracy: 0.7463\n",
            "Epoch 45/50\n",
            "203/203 [==============================] - 3s 15ms/step - loss: 0.5098 - accuracy: 0.7487\n",
            "Epoch 46/50\n",
            "203/203 [==============================] - 4s 21ms/step - loss: 0.5098 - accuracy: 0.7478\n",
            "Epoch 47/50\n",
            "203/203 [==============================] - 3s 16ms/step - loss: 0.5103 - accuracy: 0.7493\n",
            "Epoch 48/50\n",
            "203/203 [==============================] - 3s 15ms/step - loss: 0.5080 - accuracy: 0.7514\n",
            "Epoch 49/50\n",
            "203/203 [==============================] - 3s 16ms/step - loss: 0.5095 - accuracy: 0.7486\n",
            "Epoch 50/50\n",
            "203/203 [==============================] - 4s 21ms/step - loss: 0.5075 - accuracy: 0.7470\n"
          ]
        },
        {
          "output_type": "execute_result",
          "data": {
            "text/plain": [
              "<keras.callbacks.History at 0x7f169012c1c0>"
            ]
          },
          "metadata": {},
          "execution_count": 8
        }
      ]
    },
    {
      "cell_type": "markdown",
      "source": [
        "# 3.) Test your model and compare insample Accurracy, insample random walk assumption Accuracy, Out of sample Accuracy and out of sample random walk assumption Accuracy using a bar chart"
      ],
      "metadata": {
        "id": "yFhO9vMjsWPk"
      }
    },
    {
      "cell_type": "code",
      "source": [
        "test_data = scaled_data[training_data_len - input_size:, :]\n",
        "x_test = []\n",
        "y_test = np.array(stock_data[[\"Close\"]].pct_change().dropna())[training_data_len:, :]\n",
        "for i in range(input_size, len(test_data)):\n",
        "    x_test.append(test_data[i-input_size:i, 0])\n",
        "\n",
        "x_test = np.array(x_test)\n",
        "x_test = np.reshape(x_test, (x_test.shape[0], x_test.shape[1], 1))\n",
        "predictions = model.predict(x_test)\n",
        "\n"
      ],
      "metadata": {
        "id": "r1Xj6Ji-rwnM",
        "colab": {
          "base_uri": "https://localhost:8080/"
        },
        "outputId": "fb6dd176-da61-4dc6-b9fe-d47a5ae1047e"
      },
      "execution_count": null,
      "outputs": [
        {
          "output_type": "stream",
          "name": "stdout",
          "text": [
            "51/51 [==============================] - 1s 5ms/step\n"
          ]
        }
      ]
    },
    {
      "cell_type": "code",
      "source": [
        "# This line of code will calculate the predicted direction of the stock movement based on our binary forecast\n",
        "predicted_direction = np.where(predictions > 0.5, 1, 0)\n",
        "\n",
        "# In-sample accuracy\n",
        "train_predicted_direction = predicted_direction[:training_data_len-input_size]\n",
        "train_actual_direction = y_train\n",
        "train_accuracy = np.mean(train_predicted_direction == train_actual_direction)\n",
        "\n",
        "# In-sample random walk assumption accuracy\n",
        "train_random_direction = np.random.randint(0, 2, size=len(train_actual_direction))\n",
        "train_random_accuracy = np.mean(train_random_direction == train_actual_direction)\n",
        "\n",
        "# Out-of-sample accuracy\n",
        "test_predicted_direction = predicted_direction[training_data_len-input_size:]\n",
        "test_actual_direction = np.where(y_test > 0, 1, 0)\n",
        "test_accuracy = np.mean(test_predicted_direction == test_actual_direction)\n",
        "\n",
        "# Out-of-sample random walk assumption accuracy\n",
        "test_random_direction = np.random.randint(0, 2, size=len(test_actual_direction))\n",
        "test_random_accuracy = np.mean(test_random_direction == test_actual_direction)\n",
        "\n",
        "import matplotlib.pyplot as plt\n",
        "\n",
        "labels = ['In-sample Accuracy', 'In-sample Random Walk Accuracy', 'Out-of-sample Accuracy', 'Out-of-sample Random Walk Accuracy']\n",
        "model_accuracies = [train_accuracy, train_random_accuracy, test_accuracy, test_random_accuracy]\n",
        "random_walk_accuracies = [0.5, 0.5, 0.5, 0.5]\n",
        "\n",
        "x = np.arange(len(labels))\n",
        "width = 0.35\n",
        "\n",
        "fig, ax = plt.subplots()\n",
        "rects1 = ax.bar(x - width/2, model_accuracies, width, label='Model')\n",
        "rects2 = ax.bar(x + width/2, random_walk_accuracies, width, label='Random Walk')\n",
        "\n",
        "ax.set_ylabel('Accuracy')\n",
        "ax.set_xticks(x)\n",
        "ax.set_xticklabels(labels, rotation=45)\n",
        "ax.legend()\n",
        "\n",
        "fig.tight_layout()\n",
        "\n",
        "plt.show()\n"
      ],
      "metadata": {
        "id": "ZP_GJ8X-Wkln",
        "colab": {
          "base_uri": "https://localhost:8080/",
          "height": 333
        },
        "outputId": "c0ae9e51-a39d-4695-f357-58eb91f06dad"
      },
      "execution_count": null,
      "outputs": [
        {
          "output_type": "stream",
          "name": "stderr",
          "text": [
            "<ipython-input-10-0ae27e7848c5>:16: DeprecationWarning: elementwise comparison failed; this will raise an error in the future.\n",
            "  test_accuracy = np.mean(test_predicted_direction == test_actual_direction)\n"
          ]
        },
        {
          "output_type": "display_data",
          "data": {
            "text/plain": [
              "<Figure size 432x288 with 1 Axes>"
            ],
            "image/png": "iVBORw0KGgoAAAANSUhEUgAAAacAAAEYCAYAAAD4czk4AAAAOXRFWHRTb2Z0d2FyZQBNYXRwbG90bGliIHZlcnNpb24zLjUuMywgaHR0cHM6Ly9tYXRwbG90bGliLm9yZy/NK7nSAAAACXBIWXMAAAsTAAALEwEAmpwYAAA++0lEQVR4nO3dd5hdVfXG8e+bEEjovZeEXqSH3nsP0qRIE3406dIiSC9KURBQIKgQEQRpIXQBQWlBAkgXQWooEiCBBAhJ4P39sfaES0jCBGbm3Ll3fZ6Hh7llZnbuPXPXOXuvvZZsk1JKKdWTLlUPIKWUUhpfBqeUUkp1J4NTSimlupPBKaWUUt3J4JRSSqnuTFH1ACbXrLPO6p49e1Y9jJRSamiPPfbYe7Znq+r3d7rg1LNnTwYPHlz1MFJKqaFJeq3K35/TeimllOpOBqeUUkp1J4NTSimlutPp1pxSSp3LmDFjGDJkCKNGjap6KGkCunfvzrzzzku3bt2qHspXNF1w6tn31kp+76vdd+n4X3rShx3/OzvSSTNU9Hsb+HVth9d0yKo/Z7oFe9Nz+imQNOEnzb18m//e8T01ZHi7/44JWabLK5X83ta8prZ5//33GTJkCL169eqAQbVe0wWn1PaqC/iV/No0mUbNsCA9p5lEYEqVkcQss8zC0KFDqx7K1+SaU0qpnSkDUx2r1/cmg1NKKaW6k9N6KaUO1fP8tyZw74Tua51Xf7HFNz5HEptvswM/P78fAGPHjmXDFRfne8uvyIWXX9Pq37XZastw1a33MtPMs3yn56RvlldOKaWGN8000/DfF55n1KefAjDo/nuZfc65Kh5VmpQMTimlprDmehtx/9/+CsDtN13PpltvN+6xD4cN47C9f8j2G63Brn024j/PPwPA8GEfsN8u27LNBqtx0lGHUNs5/JYbrmGXLTfgB5usxSl9D+Pzzz/v2H9Qg8vglFJqCptuvS13DLyBz0aN4sXnn2Xp5XuPe+y3v/o5i39vGa6760EOPuZ4fnbYAQBcfO6ZLL/yqtx4z8Osv+kWvP3mEABefvEF7rz5RvrfeAd/ufN+unbpym03XlvJv6tR5ZpTSqkpLLrE93jrjde5/abrWXO9jb7y2BOPDuJXl/wRgFXWWJvhwz5g5IiPePyRh/hVvysAWHuDTZh+hhkBeOTBv/P8U0/ywy3XB2DUqFHMPGtlBbwbUganlFLTWGfjzfjVacfz+7/czPDhw771z7Fhqx124tC+J7bh6FKtnNZLKTWNbXb8IfsdfgyLLLHUV+5fYeXVuLVMyz368APMOPMsTDvd9KywyurcNuA6AB649y4++nA4EFdXd986kPffi82rHw4bxltDXu+4f0gTyCunlFKHevWQub9+ZweULwKYY655+OFe+33t/gMO78uJRx7E9hutQfceU3Paub8FYP/Dj+GYA/+PbTZYjeVWXJm55pkXgIUWXZwDjzqOA364LV988QVTdOvGsaedzdzzzt8h/45mkMEppdTwRo4c+bXaeiuttiYrrbYmADPMNBPn/f7Kr33fjDPNzCVX3TDBn7lpn23ZtM+2X7v/9oef+u4DTjmtl1JKqf5kcEoppVR3MjillFKqOxmcUkop1Z0MTimllOpOBqeUUkp1p11TySVtCvwa6Ar8zvYvJvK87YDrgJVsD27PMaWUKtZv3bb9eSd9+I1P6dq1K4ssviRjx45lnvkX4PTzLmH6Gb57S/qb/nIVzz71BMeedvZ3/lnjfuad93HZNQMZ8IdfAfDzC/7A768ewEsPDgTg5r/+nUuvupGBl583we+//JqBDH7qOS687Br23HNPttxyS7bffvs2G19HabcrJ0ldgd8AmwFLAjtLWnICz5sOOBR4pL3GklJqbj169OAvd97PDfc8zAwzzsQ1/S+tekgTtXrvZRn0+NPjbj/82FNMP+20vPveBwA89NhTrN572aqG12Hac1pvZeAl2y/bHg1cDWw9geedCpwJjGrHsaSUEgDLrLAS777zNgBPP/EYu229MT/YdG12//7GvPrfF4G4Ijp8n904YNft2WqtFTn39BPGff+Aa65kq7V7s8uWG/CvwV+eU7/5xuv834592H6jNdhnp615+803ANjzsBM5oO8ZrLrl7iy42lbc99Bg9vrJSSyxzrbsedjXa/PNNstMTD/tNLz0SpRDevOdd9lu8/V5aPCTADw0+EnWWGlZbv7r31lly91ZfuOd2XDH/fnf0Pcn+e8+/vjj2XPPPTtNa4/2DE7zAG/U3B5S7htH0grAfLZvbcdxpJQSAJ9//jn/fPAfrLvRZgD0WngRLrv+Nv5yxz/48RHHcv6Zp4577gvPPc1Zv/091931IHfefCPvvDWEof97h4t+9XP633gH/W+4nZdf/Pe45//ihKPps/3OXHfXg2z+/R0484S+4x4b9uFHPHxzf8496Qj6/OhwDt/nhzx773U8/e8X+dczL3xtnGustCwPDX6KF156lUV6zc+qKyzNQ4OfZOzYsTz53H9YadmlWHPl5Rl0c3+e+Ouf2WnrTTjrt/0n+u8+6qijGDp0KJdddhldu3Zti5ey3VVWvkhSF+BXwJ6teO6+wL4A88+ftatSSpPn008/5QebrMW777xNr4UXZdW11wNg5IiP+NnhP+b1V/6LJMaOHTvue1ZZYx2mmz7WpRZcZDHeGvIGwz/4gN6rrcnMs8wKwMZbbctrL78EwFOPPTquvcaW2+3IeWd8eVW01UZrI4mlF1+YOWadmaWXWASApRZdiFeHvMVy31vsK+NdvfeyPDT4ST7/4nNWW3EZVl7+e5xy3qU88cwLLL5QT7p3n4oXX3mdHQ/oy9vvvsfo0WPoNf8EahYCp556Kqussgr9+vVri5eyw7TnldObwHw1t+ct97WYDvgecJ+kV4FVgYGSejMe2/1s97bde7bZsmdKSmnytKw53T7oKWxzdf/fAfCbs89gpdXX4oZ7Hub8y65m9Gdfri50m3LKcV936dr1O02HTVV+VpcuXZhqqpqf26ULY8d+/eeusdJyPPTYkzw0+ClWW3EZppt2GkZ9Npr7Hh48br3p4OPP4qAf7cjT9/yFS848jlGfjZ7g715ppZV47LHH+OCDD771+KvQnsHpUWARSb0kTQnsBAxsedD2h7Zntd3Tdk9gENAns/VSSu2lR4+pOeaUM7mi34WMHTuWESM+Yo455wJg4LVXfeP3L738ijw26EGGD/uAMWPGcNctA8Y9tuyKK3PHwOsBuO3Ga1l+5dW+9TiXWKQXb73zHg/88wmWL1dVyy25KBdfcT1rrLQcAB9+NJJ55oyT9f7X3jzRn7XpppvSt29ftthiC0aMGPGtx9TR2m1az/ZYSQcBdxKp5H+w/aykU4DBtgdO+ieklBrSvvd9/b4OapkBsMT3lmGRJZbi9puu40cHHMLPDv8x/c4/h7XX3/gbv3e2OeZk/8P7stvWGzPd9DOw+FJLj3us76lncsIRB9H/4guYaZZZOeWXF37rMUpileW/x4cjRtKtWzcAVltxGfpdeQOr914GgJOO2I8d9juGmWaYjvXXWIlX3nhroj9vhx12YMSIEfTp04fbbruNHj16fOuxdRTZrnoMk6V3794ePPjbX1z17FtN7sWr3Xfp+F/aiv0fbaGpXlPosNe1Eid9970/43t+k7+wxAKzT/pJHRCcxm+Z0VGW6fJKJb93cl7T559/niWWWOIr90l6zPbXllk6SlaISCmlVHcyOKWUUqo7GZxSSu3MdLblg2ZSr+9NBqeUUrvq/uHLvP/x2Lr9EGxmtnn//ffp3r171UP5mso24aaUmsO8j5/JEI5h6AwLAprwkz58vt3H8b9hn7b775iQ5zW0kt/b2te0e/fuzDvvvO08mMn3jcFJ0lbArba/6IDxpJQaTLfRw+k16KeTflIHZEBullmlnUprpvV2BF6UdJakxdt7QCmllNI3BifbuwLLA/8FLpf0sKR9S6uLlFJKqc21KiHC9kdEM8CrgbmAbYDHJR3cjmNLKaXUpL4xOEnqI+lG4D6gG7Cy7c2AZYEj2nd4KaWUmlFrsvW2A861/Y/aO21/Imnv9hlWSimlZtaa4HQS8HbLDUk9gDlsv2r7nvYaWEoppebVmjWna4HaNPLPy30ppZRSu2hNcJrC9rguVuXrKSfx/JRSSuk7aU1wGiqpT8sNSVsD77XfkFJKKTW71qw57Q9cKelCovbIG8Du7TqqlFJKTe0bg5Pt/wKrSpq23B7Z7qNKKaXU1FpV+FXSFsBSQHcpCjfaPqUdx5VSSqmJtWYT7sVEfb2DiWm9HYAF2nlcKaWUmlhrEiJWt707MMz2ycBqwKLtO6yUUkrNrDXBaVT5/yeS5gbGEPX1UkoppXbRmjWnmyXNCJwNPA4YuLQ9B5VSSqm5TTI4SeoC3GN7OHC9pFuA7rY7dxerlFJKdW2S03ql++1vam5/loEppZRSe2vNmtM9krZTSw55Siml1M5aE5z2Iwq9fibpI0kjJH3UzuNKKaXUxFpTISLbsaeUUupQ3xicJK09ofvHbz6YUkoptZXWpJIfVfN1d2Bl4DFg/XYZUUoppabXmmm9rWpvS5oPOK+9BpRSSim1JiFifEOAJdp6ICmllFKL1qw5XUBUhYAIZssRlSJSSimldtGaNafBNV+PBf5s+8F2Gk9KKaXUquB0HTDK9ucAkrpKmtr2J+07tJRSSs2qVRUigB41t3sAd7fPcFJKKaXWBafuta3Zy9dTt9+QUkopNbvWBKePJa3QckPSisCnrfnhkjaV9IKklyT1ncDjP5H0nKSnJN0jKTvsppRSatWa02HAtZLeItq0z0m0bZ8kSV2JiuYbEennj0oaaPu5mqc9AfS2/YmkA4CzWvOzU0opNbbWbMJ9VNLiwGLlrhdsj2nFz14ZeMn2ywCSrga2BsYFJ9v31jx/ELBraweeUkqpcX3jtJ6kA4FpbD9j+xlgWkk/bsXPngd4o+b2kHLfxOwN3D6RMewrabCkwUOHDm3Fr04ppdSZtWbNaZ/SCRcA28OAfdpyEJJ2BXoTreC/xnY/271t955tttna8lenlFKqQ61Zc+oqSbYN49aSpmzF970JzFdze95y31dI2hA4DljH9met+LkppZQaXGuunO4ArpG0gaQNgD8zkem38TwKLCKpl6QpgZ2AgbVPkLQ8cAnQx/a7kzf0lFJKjao1V07HAPsC+5fbTxEZe5Nke6ykg4A7ga7AH2w/K+kUYLDtgcQ03rRENiDA67b7TP4/I6WUUiNpTbbeF5IeARYCfgDMClzfmh9u+zbgtvHuO6Hm6w0na7QppZSawkSDk6RFgZ3Lf+8B1wDYXq9jhpZSSqlZTerK6d/A/cCWtl8CkHR4h4wqpZRSU5tUQsS2wNvAvZIuLckQ6phhpZRSamYTDU62B9jeCVgcuJcoYzS7pIskbdxB40sppdSEvjGV3PbHtq+yvRWxV+kJIoMvpZRSahet2ec0ju1hpVrDBu01oJRSSmmyglNKKaXUETI4pZRSqjsZnFJKKdWdDE4ppZTqTganlFJKdSeDU0oppbqTwSmllFLdyeCUUkqp7mRwSimlVHcyOKWUUqo7GZxSSinVnQxOKaWU6k4Gp5RSSnUng1NKKaW6k8EppZRS3cnglFJKqe5kcEoppVR3MjillFKqOxmcUkop1Z0MTimllOpOBqeUUkp1J4NTSimlupPBKaWUUt3J4JRSSqnuZHBKKaVUdzI4pZRSqjsZnFJKKdWdDE4ppZTqTganlFJKdaddg5OkTSW9IOklSX0n8PhUkq4pjz8iqWd7jiellFLn0G7BSVJX4DfAZsCSwM6SlhzvaXsDw2wvDJwLnNle40kppdR5tOeV08rAS7Zftj0auBrYerznbA30L19fB2wgSe04ppRSSp1AewaneYA3am4PKfdN8Dm2xwIfArO045hSSil1AlNUPYDWkLQvsG+5OVLSC1WO59sQzAq816G/9OTGvgit5DWFRn9d8zVtY534OF2gLYbxbbVncHoTmK/m9rzlvgk9Z4ikKYAZgPfH/0G2+wH92mmcHULSYNu9qx5HI8nXtO3la9r28jX9dtpzWu9RYBFJvSRNCewEDBzvOQOBPcrX2wN/s+12HFNKKaVOoN2unGyPlXQQcCfQFfiD7WclnQIMtj0Q+D1whaSXgA+IAJZSSqnJteuak+3bgNvGu++Emq9HATu05xjqSKeelqxT+Zq2vXxN216+pt+CchYtpZRSvcnyRSmllOpOBqeUUkp1J4NTSnUmq6SklMGpKUhaStKcVY8jtY5tS1pT0ulVj6VeSFpe0tLl6/zc6kQkzfttvi/f5AYnaRpgTyD/sDuXIcBykhaseiB14gfAOQC2v6h4LKmVJM0GHC+p1+R+b35QNTjbHwNjKJud8w+70xhKVFBZAppvqm8C/95jgTclrTaRx1N9mgKYE/je5H5jBqcGJWlhSRuVmz8Dukoavyp8qiOSFpf0kKTVgW7An4GTJc3RbJVTytTmGpJ2k7Ra+ff/D1iz5fFqR5gmRdJ8kqaz/TZRbOEISfNPzs/I4NRAWs4mJc0BbAqcLek0YD3gX8CMlQ0uTVDNe7Y08DowANicaCEzO/ACsEh5TsP/vda8HjMRn0/LA8dJOgl4BNhb0mSfhaeOU9aYDgLulLQi8CJwB+Xzp7XHcW7CbRCSVM42NwUWBy4nLqn3B6YiqrqPBb5v+9HKBpq+RtIWwEnA/rYfK7UoVwH2Ia4UXrG9QYVD7FCSNgd+DqwNjACmBU4BRgKHAQfa7i+pq+3PKxtoGqfm82dVYDbgAeCHwKLAdMAWwF22f9jqn5nBqXFIWhe4FNjL9v3lvq62P5e0K7AG8ITtfpK65PpT9cpC8U3APrYfKfe1/KH3ALoDlwHn2v57hUPtEJJWBv4AHGz73prjtwsg4ox8P2Clsp6a6oSkTYBLgF1sP1Tum42YATiGuHI62/b9Lcf4pH5ew08TNJltgF+VN79rmSIRgO0/ATcDG5XbGZjqwwzA2zWBaYoSmKay/antYUQbmbkrHWXHmR64tgSmKQFDHK+2P7f9a+AZylRnqp7CTMAhxInxQ6UFEsD7tp8FDgb+DSwDrVszzODUWN4lpvAAupQDYClJC9c8Z5lyIKUKTCDL7HngM0k/gHHV/NcDTpM0laS5iWynf3XsSCvTHdhD0gK2R9v+QtKGZaoPSUsRGYzDKh1lGsdhGPAOMHq8Y7yXpGlsf0h0Ot9I0pStybbM4NRJ1SwcLyJpprKf6VFgZ0nLAFNIWpaYEupWvu0/wNblQEodrGa6bhNJh0k6xPZnRF+zVSRdIGkz4LfE/Pxntt8Cdrb9fKWDbwc1x/BKknaR1NP2LcS//yJJq5Sp6vMoV1BEev16tl+rYMipqHnvpqu5+xOgTwlWYyWtAPyCuBqGWDM8oZx0fOOVU645dWLlbPIM4BZgHmI+fltgV2A40As4w/aAXGOqDyX54UzgQCIz72Liw7cXsRftY+Be27c2w4J/eT3OJtbdNgDOBwYBWxLT1COAi23f0pp1itRxyonUEcCDwHPESdYNRG++4UQyz0m2b/xWPz/f685J0nLAFUAfYGdgN+DV8v/PiYyZLrb/nX/U9aEkOFxD7Dubm8hA6wo8BexdprBaEgAa/j2TtAjwG2BvYEliP8y9wN22+5fndLc9qhlej85E0vrEicRexEnVusQV78XEScbswEu2B33b965dmw2mtlUzLbQoMCvRqHFBYLvy9dHAtcCPa6eB8o+6euUKoQuRXjsfcCqwMpHB9B7wgaSjWq6UGv09k7QKMUV3CLGmdgawLPFBd5qkrsCVwGfQ+K9HZ1Dz+TM3MAewPTA/cRwfA/QFetg+p/b7vu17l2tOnUTNgbE28CvgJWKD5gbEpfMzwH+JRcnpJv6TUkeT1Js4cRhqe0S5+w3ifVqA+BAe0CzTrmUt4hJgBtv/BhYCnrH9PjGl9xzwUFlzy6BUJ8rnz8bAkcDDwNvE9PR+Za3wbeD75Yr4O8srp06iHBgrEVdJ/W2/Ws4uZwI2k2Rijn43209XOdb0pXKWeTgwwvagcvco4qrhEmLv2Z6t3fvR2SkK2V4L/LqkGEMEpJ9JuozYfHxoCVqpjigqc+wMXFI+f1qyfnuUzbdTAT+y/WJb/L68cupcViEWiueRNGWZAjoR6AHsBJyagal+SJqnZNv9DZhNUkvx3ZeJtZYLgJ1s/63c3+iBaQqiRNMg4LCaTK/XiGnpF4gp6bsqGmKaiLLn7Cxi6hWAkvX7AHACcaL1x7YKTJAJEZ2CpCWAtW1fIml/YCvgeGIqZHS5gupavm74s+/OQNIMwOPAObYvkrQ7UY7nPseG6KZStjecCPyf7WGSfkuU2drW9vBKB5cmSdLixGb+D4gg9BjwG9sflMfnIM6t3m3Lz5+8cqpj+rJA4nLASpL+z/bFxJn4CcDyLdldtkdD4599dxZl0+EewMGS9rL9R+A+YPMSqJqK7aeIZYSLynTQgcTG4jtLIE91RlKXsn9yB+BQInnnx8DqwH6SZgWw/T/b75av2+zzJ4NTfZu9/P8vwF1EdYd9bf8S+CdRLHSaisaWJkDScpKWLvvKHgB+BPxU0s7liumvwBPVjrLjKFq3rAhge2tiM+0fiI2ZRxAbxxevboRpYhwloz4GbiSmXvcn3re9ia4HP9aXZYraXE7r1SlJswB/B86y/ccydbcjscH2RtuXSupl+5VKB5q+QtIpQEt23vNlz9KBxE75/W1fWekAO5CkqYgU8bHANbYfL/c/QOzv2rJk6KU6I2lJIiu4T1kuWIJIxpqPOJZHA3O7HTsc5JVTHakpCTIvsTP+WOBQSTuVqburiA22a0qaLwNT9Wres3Uk7Wb7BOBJYtp1ifK0fwN/JFJtG1rt60HsX+pPBKc+JdsUot36jOXxVCdq3rtpiK0OQ4HrSvLV88CdxJTeEcDw9gxMkMGprpR08a2IabyetgcSH3J9Je1ezmamISqPv1HlWFMo79nmwEXEHjNs/xR4GThR0i+B3wGX2/5bywdAoyqvxxZEtYDFylrT9cCURKPA44nU+t1qUslTxWr2UW5FZOVNRUzjvUuUJIIotvsykQzR7u1KclqvjpTNiZcS6bSP1Ny/HnGJPZLo63PDRH5E6mCSpgX6EfXf/lHOMkeXx7YgyhS9ZvuvVY6zo0iamaixdmTNvq6WjNPliS6/f7Z9a0VDTBNRNvifT/TSaukH150oK9VyYnxkOWlud7kJt75MBzxs+5FSh+0z4mT0XklrAVPa/iDTxatV+/rbHlmuhhYB/lETmBYG7rQ9dvzvaVTldfiCWE96sdw3laPy+hu2n5d0taOGYMO/Hp1FzXuxGrE2eH/Z1zTG9ijgh5KWB0bafrGj3ruc1qtQzRzvspJmJDKZViyZXp86ytmsIWlH4OOWfQX5R12dmumPzRVtL6YmElfmUrQoaSlXdB5Rmgho3Pes5hheHdi07Fl6HDhK0rS2PytX/teVY7yl+WVDvh6dSc0Uc0sjyzFEwWiAz8txvoqkRWw/0bLBtqPeuwxOFaqZn78EWNj2P4jF839KWkvStkQ/puH5x1wfynu2EdH24hnbnxBp/rMQJXiuAP4E9LP93wqH2iHK67EJ8W8eWe7uT1w93S5pH6IaxoW2h7vBW4B0JjXv3R8U7dQHEv3gDgSmLiccVxHdmjtcrjlVSFIvoo/NPuOtMZ0OzExkM11i+46KhpgK1fTDknQJ0XPp6pY1JsUu+dmIKvFv2H6i0aeuypn3jETh2nNcyjCVx2YGdiHOxl9sSQZp5Nejs5G0MvHe7V1OjFvq5/2OOEleHDjNUdS1w+WaUwVqPuhmAN5qCUySepTpvONqb1c51mYnaXrbH9UEpi5ELcPu5Sktsw8zAM85qsMDjT91Vf59wyS9SbSaF9CtrLtNTySJjB3v+ali+rKJ5YLEGtM/FJtpu9h+RtKG5akz2369qpOKnNbrIJIWktRH0uz+sjXCi8AYSTsA2P5U0gaSzpTUjdjolioiaS7gLknHlveve3nvBgInS1rT0QhvVeIKuE1aBdQrSb0k3SlpDUk9y31TEWulWzqMVlSEOJvoOZbqgKQ5JC0EUDO1+gGwrqRFbY8t790GwPq2RxJ7nSo7qcgrp45zLlHy41+STgL+bftlSQOAVUs23u1EyvhhtsdUNtLUYk5gUaIqx9TAUpIOt32dokXJnyXdBKwDHG37hQrH2hG+B6wHPE2U0vq97WskHUEkPPwJ+JAv23O/U+FYU6HYVPsk8L6kgcDpxMboe4n3c0dJfwc+Jk4qfgLVX+nmmlMHKWfXLW0BNiIWj58BLif+6Dcjporuyj0g9UPSXkTh3UuJk4udgDuIheKPiPT/lumQhl5TKdl2txFXif8kNtO+Ddxd7tucSCUfavvhRn89OhNJxxInWwsRm2nfBX5JrJOuTRzXHxFr3DdWNc5aeeXUcV4HVgT+ZnsHSX2AAUSb48+IhcePoDn2xNS7mvfgJaJdydPA05KOI9ZT7iYKmJ7Ysq7SyO9ZWScdLulnxAL6mZLGEo0D1yWSH+6wfUnL9zTy69EJPUtspN2eqNbxCyLl/xgiYWX1lvXVevn8yTWnDlDe7LeIA+JHktYlyhL9lFi/mBlYpuX59XBgNLuW96BkMXWRdIekJ4iTiIOJqbyBtQv+jaxmnfRVAEnbEWfep9hejEinf6ia0aVvYvsm4mLkCCJ5ZyXi5HhW4GxFh+IR5bl18fmT03odpCbt9nSinfrJjt5MqU61ZFWWNPF7gOttn1iT7dSUJB1J1F87wfZp5b4uNQEs1ZGa43hp4EjiSvcC2+eUx2dw9B+rK3nl1E5qdl8DcTbiaGv8GDCiJTApWmGkirW8DyVDD/jK1cIIoh310JaHOnZ01VNo+bw4j2gx/1B5rGsGpvpV8968RtTHe7QmMHWtx8AEGZzaXE1Q6jHe/V0BbP8eeFLSQc1+Bl4PJM0iaRpH36VeRNbZ9LUnF44qEFcDx5WrqIbW8m8v6cdzw7iTqy/K12OJbK99y+08huuMounlYjW3Vda0TwAWUmlfUs/vXSZEtKGWhURFSZA9JA0mqgVcWz78Wj7w/gbcX88HRjMoe3SOAroqWjkMA94ri8JdKFdI5X29T1Jv2/+rcMgdohzDfYjF8vckvQccURIiWhbLfwqsXOlA0zjlin9q4uqoO9El+4SWx8t7KmLv0r3A8I4f5eTJK6c2UhOY1iL2Kv0a2ATYrHwItpx9mqi79swkflxqZ5LmcFTLvoXIXjoa6Emppl07TVWTHPFmx4+0Y9RM2SFpOWJtog/RYG5loslly4fclLZHO9rQp/pwADHd2qtsoP2YsolfUtcyS2PbI4iknherG2rr5JXTdyRpAeJv9vXyB74okRHzBVEMdB9HZeZ5bQ+B+r6UbgblfTpH0hS2d5Y0BvgBcCLQW9JrRAbla8BY23+qcLjtTtKswOmSTiwbZ00Uct0a2J1o1T1C0gq2H3dpC5KqJ2l2YCnbJ0g6CzhV0k+J4NSylPC5ojwR5fYH1Yx28uSV03e3G3CfpJ7lbHsocQZzKbB5CVpbAbsqeqSkipX36UhgSkn9HLUNryGqG/yP6AL6CXFy8X5lA+04UxN77c6SNCeRALILsA+wre1XFPXWfitpngrHmWqUabptiCWEjWwfTRy/FwGrAr+R9AdJNwJXl0DWaWQqeRtQVBHfDNiOWLf4NfAmUQpkEaKTZF9n5Ye6Uq4YLgPesb2PpFWI9/AT4GyXVtT1simxPSlq5R1A9PbZjwhOewHnADMR1SD6uqIK1WnCJE0P7EHM2Nxi+86yUbwP8fnzGjFtPdz2s9WNdPJlcGojkk4jAtT3gXmBrYgyRcOJXjY3NcOHXL1qSUYpayYzEc3UPlK0driCqA6/j6Q1gB8C59n+T4VDbnfjH4+Knj7HEBsz9wW2JTaHz0zs8borj+H6I2kGYvp1CeBm27dLOhOYj9iL9lKlA/yWMjh9B4p+KIsB/7T9gqJ+1TbAdmU6b3ai1fGw/KOuD2WK9SjiyvYZ26eXYHU58JHt3ep1U2J7UDS7XJfY+nASUT1gH6Lm2lG2Pyhrc01RCaMzaNmCImkFYn3wHWI5YT9gKWCA7b9KOg/4o+3Hqxvtt5drTt+SovV0f2LR+NRy5fRzoiTI3ZIWtP1u2XhbNyVBmo2khSUdWr7eADgN2JOorH2qpHPKe/QjYDZJSzdRYGppbTGICEYXANMSFfQ/BS7Sly0xUsUkTQvjEhz6EE0Bf0hMva4L/BZ4iuhmu6ntwzprYILM1vtWJC1DZHbt4uh4uhoxjbdnzZn43MDLVY4zAbHn4yeSnic+cHcnCmBuQtQXu1vSF7aPlrRls1whKErZHAhcbft64PpygnWe7fVK5lePkm6fKlam7k6RdCWRuHMUsYywA3Es70Mk8vQjPtffqGiobSavnCaTotLD4kBvYP1y9yAiEG0IYPvI3ANSH8p+sl8S79VrRMuSPYGzbD9GrDcdKmlhyl6eJjE1sba0nKTFAWz/jGh+uZjt1934/ak6kxmJE62liDTxQ4iTrL2JfmOvEptuv2/7ws6W/DAhGZxaoWUxvSye97D9F+KsczNJO5Upu+eBuRTlcDSJH5famaSeku6TtLKi0dqdxNrgIrZHEe1LeknahljsX972S80w9SppRUlLEcfrQURm4paS1i4zAosQe/RSHZA0m6Rutl8jlgxOAOa0/QTRB+4c208SJ8eP0UCzNTmt1wolw2sbokPk1JJ+aru/pNHEZs4+xFnoubabYV9MXapJOpkCWADYn0jtv5C4Qrpc0rJE+ZYNiamQk2w/N973NyRJawPXER2XewCnEEkQpxGbkF8BDrL9YqO/Fp1BWR64Ehgm6YCShXc6cIGiZclI4PyywfZoYHfb/6puxG0rs/UmoeUPtGyevYLox9SLWIA82PatkvYAdgbudqn0m6qhUlZHUndiX0434O9Ee4e9gUOJKZHDy/s6c8lGa9gP4ppjeCYik/R54gz7R8RemL7ERuOzicX0SztLBYFGVxIgLiJOpC4hGl++AqwGjLJ9oaSfALMTtTobah9lXjlNQvmj3hhYmvhQe7IkQAg4t3wY9pc0EjhM0ouOpl6pg5UP3wcl/cT2HZIuJ64S7iWmYA8lNiNuAdwI/L3lQ7hRAxOMO4a3JCqZLExcKY6WdE15yvlEID+HmDL6SNLvbI+pZsRJ0izAjLb/W4JPSxblaOBgIntymKRZbf+qTPuNabSTrFxzmoCaNaZliLTaXsBCwPGK9grXA8cDvy4H0t1EsddOm7bZ2ZV08IuBvpJOJKZZdyP2fgwFjgOuJ/7Am2ZNRVH14lCipfx/gG0l9bI9nCjZdC3QraxhnAHclIGpOpKmJpIdfitpY9tDiaumIcCDwJnAXMSU9aUALe9XIwUmyGm9iVJUFz8EuML2QEmbEimb7xPptiMlzekolNnw6xWdhaRViT0f6wGPAs8SH75/LI9P5SjE2/Dvl2IT+J+AIbb3Kidd/YiCoGfYfqlmQ2fDvx6dhaRFgdWJE96jiU22qxKbawdLWgjYkWgaeFd1I21fGZwmonzI3QhcZfsISd2ID7ztiIPlZOL1a6b047pV++FaMvQWJDZJT0Wk4K5l+60Kh9jhyprFrkSV/J/avq7c/ydiamhf259WOMRUY/wTBEnrAv9HrDOtSWRW/p/tt1WqdjTySUWuORU1C8dzAZ/aHqQo7XKtpH/bvlTS34izztecbanrSnnv5PAx8LSiTt5PiGSIRYCGDk41x/AKxJT9MNsXS/oE2FOx2fgG27sqKmFkYKoj4wWmlgaXrwIrECdbOxPT1kdQ01+rirF2hLxyqiFpa2LB8UPgNtu/V5R4uZIo3nphpQNM49R8EC9A1MnrUhb6u9j+oma6qiuxuPx+I59ltpC0GbFO+jsi0WHLksSzK3EW/hvb11Y5xjRpEzpOSwZqP+D3tv9ezcg6ViZEFGUPyHHATsC7wFGSjnZUEdij3J6vJVkiVasEpk2AfxALxoeX1PAvyh93yzrK5y57z5ogMC1B1Hfcgkg7BnhI0mqOhomXEZUEUp2oSb5aTtL3y8nV+IGpq+1Rtne3/fdm+QzKK6dCsantDWAO4GdEiu2hRCbeycBUtj+qboQJvrZv5zjgJmJNaUNiquOcRt+7VGu8tbZuRGbp7MD5tlcomYsnAqvYfrTCoaaJkLQRUbT1dSKT9BDbz1c7quo17ZVTzRnLCooK4tcTmxC/D+xv+8pyezFgrgxM9aEEpg2JFPGFgMHAPUTVg67AcZJmaabAJGnzcpU/xtGDakni9YDYcHsX0Qoj1Ymaz58pidTwnWxvQFTLP1HSklWOrx40bXBq+aMm9nnMVu4bReyDOV7SOkSB17Ntv1rZQNNXSFqd6DT8CZFue6jtL2zfB/wVENFeveGVY7gPcDqRMt/iPWBeSScR+2KOtn13s0wHdQY1790/iE3im5f7f0LsaTpT0vcqHGLlmnZar+wluAHY2fbTkhYDpiHaKuxHVB0/y/bACoeZakhakAhMN9vupyhgeh1wme2zynNmdoOX36m5YupObK49nVhL6k3s8bqKCNyLAoNs31zRUNNElM+fM4ntDrMQMzY32L6sPP5r4HLH5uim1Myp5O8R1ap3kLQzsBaxf+mvtg+TNJvtoc2ydtFJzEyUkdpB0j22n5W0LXBX2fdxRiMHJknT2h5Zczx+Tqy3HQXMBLxI7IeZoZyBt3xfHsN1oly99iKSU56zPUBSD+LzaE/FJvGLbR9a6UDrQNNO6xELj88SB8qDxJnLfcCc5fH3oPEzvOpZzbz8Qop+S08TySqDgB8ryvA8T1TueLC6kba/kol3vqT5W+5zlK05lFh3O832kcSerkUV7V1anpfHcMVajuWyD+9l4C/AEpJWLvvN7iS2rPSRNK+kZv5sBpp0Wk9fFkqcChhb0o57EynJx9q+s+IhNr2a/UqbE/t2niXaYPyYSHzYnLiSOqf8sTfsFUI5s/4z8EdgIJFR+k45bqdw6d4raSuiPt5xOR1dP2qmYdcElgXeBm4hml5uA5xg+9EyTTu97XerG239aPjoPKFF4BKYFiD62cxVNtqeCJxq+85cOK6OpOkBSmCaDzgG2M32tsRaSl9i0+1VwAiiPBHlexouMAGUM+t7iS0Nz/DlCdU8wPOS1lSUbNoCOMZRCzKP4TpRAtNmRF+xBYAtgduIK6UBwFnlCmpUBqYvNcWVU9lguxpxtvIyMVf/CFE37+zyhz2T7SGNevbdGZQrhNuIheELypXtFcAvbT9SnnMBMK3tH0mawfaHFQ653dWcda9OTDs/bXvF8lh/YLDtC8rtbs6K4nVB0a1g/paEBkm/JdazB5QTh1OAuW3vXfai3Wp7cIVDrjsNe+WkKFuDor7ahcAyRLPAHYg6a/vYPhvA9se2h5SvMzBVpFwhHA/sIWkP258R1TpWUlTYhpjWaqn40BSBqdx8HFgRuF3SveWE6ic1galrBqb6UE6qDiCO45XK3dMAS5SvuxDTtF0BbJ+cgenrGi5br+Vsukx7LE20oN7LUWp+NyLFFuIqatzaRlXjTaHmg3gk8E9iI+L7xBrKRcBSkj4kpkR+Wt1IO0bNFdNGRFCamkgZP504ybqeKATacgxndfw64WjJcgWxJeX7koYQnYZvlPSWo0HpzETiytzA23lS/HUNdeVUzlgel3R4uWtOovvnTgC2rwAeADYiDppuGZjqQ80H8Y3A/cR8/BnE3p3diCoHHwAH2L650ddUyuuxDnHV/zqwEtFcbp6SZvwGMKDMEOQHW52oOS57AcsDPyBmAz4lTiZOltSPKMx7uu23MjBNWMOtOUlajai3dqzt35UPvIOBe2z/ujxnd+AJ209XONQ0HkkHEI0Bzy8fuusD5wGn2L5mkt/cQGqums4E3veXG4zPAxa2vaWkKYBFbT9X5VjT15W0/xuAbYF5iK0OY4FflqfMAkxR9unlGvdENNy0nu2HFX2Y/lre+EvLycz+ZYPbWS5dUVO1JvCHORXRzPH8Mi07iKiufZqkB4G3muFKt+Y1eRFYWNKMtoc7NoffJWk+228AGZjq06zA/8oevOclfUBUNpmTaL3zWMsTMzBNXENN67VwVF/emEjR/D9HK+PfAWtL6tnoU0KdRbk6WEvSHoriu+cBb0gaoKiwvRTRW2sr20OaITCN5wWiiOt65bhdmqg4nutLdaTl86QsK0BsEv+fpN3K0sHjwN+Iah5ZQLqVGm5ar1bJlLkVONH2RZJmtf1e1eNqdjXTVqsRZVxeINaT7iH2fVwMzEjM2//M9o0VDbXdlSy7z8vXLa23x6WEK4qDbkNUFZ8LONP2gMoGnCZIsVl8K2Ck7aMk7QEsTcwG3E4kshxo+6EKh9mpNHRwApC0KtGTaQlgSF5G14fyvhwL9LX9XPljXhF42PafFbvlZ7T9TqPOy5erw72JvV0zAbsQwXiMpJ7EHq9t+XKGY1rb/23U16OzKifB/YgAdBRRTupUoCeRjDUjcJ3tWyoaYqfU8MEJvkwvr3oc6UuK5o7XEvvNfl824G4PrAM8SvyxN/ycvKKb7+3AK8Amtl+SNC1x9fiM7V9UOsA0SYrq4n2BF23/XFETbwBRougI2yMldbc9Kk8qJk9DrjlNwEcw4VJGqWPUzMtPWaavrieuGo6QtHnZgHstkep/v4sKh9yuao7F+4g0+dkpmzKJRKWzWwJTHrd1bVbi/VpV0jJlXXRrYEGgX9mDNgoa/0SrrTXFlVOqVs0a09ZENt60xPTVc5J2Ao4GTrZ9UzOdXUpajmh0+SCRbnw58H3b95Yz8iG2P6luhGl8NcfyosD/gM+ILLxDiHXTAbafKScUK9Rm5qXJ0yxXTqlC5Y95M2Iz4vHEIvHNktayfTVRdfwXkmYjOtk2i3WINYp1StLHgcAtkg4imiguWuXg0teVY3lzouXFUcT06yfAb4m1pZ0lLV0u/DMwfQcZnFK7kDSVvtqTZkWi3thyRJ2xPwHXSFq/VO5Y3/bQZkgXLyVrKJvCbyT24G1u+09EUsTiwJG2/1XdKNOElOSHnxMZlJ8AKxOtTD4htqtMS1SDSN9RTuulNidpceJq6HXgVds/L/fPQRS83Lcs/D8EdAM2bJaEFUlzEVldg2z3K/cdRPSpOtZRtTqri9eJcsxOC7xn+0NFe53PiJ5aZwF7ENPS8xFltj7Iqdi20XAVIlK1JC1GnEleQ+xfOkHS67avJObkhwArS5oT+A9wcSMHJkkLApsRvafet32rpAeAFSXtafty2xdK2hL4kaQHci9efShliPoTpYf+JenPtu8vMwK7ACeV9aX/ElPVc7l0N0jfXQan1GYUjQIvB+61/cty37TEzviWJo8PAmsT1cX3sz2oouG2O0lLEi0+bgVGA7tIupgI3GOANcvr8wAwCvhFBqb6UALTn4EjiB5w+xA94e4n1kVnBLYqiZTbEA0xs1ZnG8ppvdSmJB1NtCU52/aDkn5J7F/6J9HF9W/EFVV32683anaepBmAm4HLbF9W7psX+APxAXca0bl2H2B+olX3zRUNN41H0s+AI4FZS9WOxYm2F8faflrSlMD5QA/gZtvXVTjchpTBKbUJ1fTFknQksC7wbyIj7URiauRwYmrv57afqWioHaJUuLgU2N/2xzUbMecDHgYOsX1Dee48tt9s1EDdGSmq4p8MrFf+25FYY/qIKMj7ElF669+O/k353rWxnNZLbcL2Fy0ByvY5kkYB+xN1DW8DkPQ3ogTP8CrH2kF6EBmK6xItuEdJmtL2G5IuBBZqeaLtN8v/88OtTjiq4p9AJK+8BAwlkh7mIkpNHQ9M6ejWnO9dO8jglL6zlrPGEqC62v68LPJ3A3ZTtAx4oGSgDa92tB3D9jBJvwa2k/RmSQtvqSZuInilOlaO5+PKzY3LfW8QjR53qGxgTSL3OaVvraaszrgP2nLGOUX5+lxiremnxN6mZnMDUWNtf0kblNdmdeKK8v5qh5YmpWWPXpmqPo6ofzi4bAVIHSDXnNK3UlPGZRNir8dg4A3b15bHa9egetl+pcLhVqbsk9mRqP7wKFEd/xTbN1U6sDROzbE8B9DV9lsTeE5X4AyiPNHDHT7IJpTBKU22mj/mtYjyLXsBpwBvAge0zMOrpldRsyv7uiCyFF/NBfT6ouibdQzwXvnviCZZG61bOa2XWk3SApLmL4GpC1H77QjgC2AWYlPiZyVlmgxMX7L9Tvnv1XI7A1OFaktrlQK8RwJ9gDuJkkSfT+i5qePki54mx27AfZJ6lim7ocB5RMr05mXf0lbArmUfSEp1R9KswEU1V7Mmaj1uDewO9LE9QtIKMG7dKXWwDE6p1WyfRuyav0FSL+AfwCNEJ9cxklYm5uWftj26upGmNElTE/XxzioBagRRjmgfYFvbr0jaEPitpHkqHGdTyzWnNNkknUbUi/s+MC+wFbARkSZ+oZusL1PqfCT1JKrkzw3sRwSnvYBziH1MhwN9na3VK5PBKbVKuSpaDPin7RckHUvUFNuuTOfNDowp+3syMKW6M/5xqegfdgzRzXZfYFtgGWBm4Hrbd+WxXJ0MTukbSVqPaKb2LJH88B9ih/yxRBr5prZfrm6EKbWOpC2Iqh09gJOAGYjpvNmAo2x/IGkK22MrG2QCcs0pfQNJyxC18XaxvT3Rp6kLsKft04mq23NXOMSUWqX0YjobGEQEowuIXk3nEg0CL5I0FZEgkSqWwSlNVNl4uDjQG1i/3D2IaCGwIYDtI20/UM0IU2odSUsTG6Gvtn297R2B/wLn2f4fUdT1BNuf5RaI+pDBKX1FS0kiSTMDPWz/hfij3kzSTmX+/XlgLkmz1JQwSqmeTU2sLS1X2l9g+2dElulitl+3/UKlI0xfkYVf01eUDbbbAD8Bppb0U9v9JY0Gzik76WcFzrX9fqWDTekblKm8UcQJ1UHEVoctSwLPcGARYh011ZlMiEjAV0oSTQlcAfwC6EWk1h7saC++B7AzcLftcyocbkrfSNLawHVE0dYeRImtUUSjxwWBV4A/lmM7s/LqTF45JWDcFdPGwNLAx8CTtp8o03bnll5E/SWNBA6T9GIWL031puYkayZgYaLqw2PAj4Azgb7ErMDZwFNE48csJ1WHcs2pydWsMS1DZC31IhrhHS9pGtvXE2njv5Y0C3A38Cvg8YqGnNJElcC0JVGQ+ECizfpo4Bois/R8YHZiRmBVYMfSdyzVmZzWS5Tq4ocAV9geKGlTYBPgfSKbaaSkOW2/U56fUyCpLklahZi2OwfYk5jGO6WUJJqRqATxqO1HJa0EvDmhFhmpehmcEpJWBW4ErrJ9RDmTXA/YDngHOJk4VjLFNtWtkuTwJ2CI7b3KrEA/oCtwhu2XWtq45AlW/ctpvSZUM5U3l6QZbQ8CtgC+L2mf0k79b8AA4BrbX2RgSp3AJ0T34bUkbe+wDzAlcKKkHi3HcQam+pcJEU2ozMtvDRwMfCjpNtu/l/QD4EpJU9m+kMhySqku1SQ/rECcaA+zfbGkT4A9JX1h+wbbu0pa2vanFQ85TYa8cmpCJcX2OGAn4F3gKElH236MqJV3lKT5coNtqmclMG0GXEXUy/uHpOVt/xG4GjhE0g7luU9XN9L0beSVU3OajdiQuBqwAnAqcGhZMD4ZWNr2R9UNL6VvJmkJ4OfElPTS5e6HJK1v+0+l/NarVY0vfTcZnJrAeNMfw21fL6k78Btg/7KfaT2iJcZcLa3EU6o34yUyvAT8AJiLqIs3j6QTgQclrWK7f2UDTd9ZTus1gRKYNgeuJa6asD0KGE3sZ1qHKPB6dgamVK9qTrI2L9PQY2z/B1iSL9dHHwPuIlphpE4sU8mbgKRFiSymnW0/LWkxYBqiTcB+RNXxs2wPrHCYKX2jUtvxZOBntm8t921LVIJ4BdiBaO/yZKaLd24ZnJpAqTB+HFGWaApgLWL/0l9tXyppNttD84851aOaK6buwB+A04m1pN5EIsRVwOrAosAg2zdXNNTUhnLNqTl8QXSxXY/IYvolkak3Z3n8Pci9H6m+SJrW9sia4/JzoDtwFDAT8CKwJjCD7Z/UfF+eZDWAvHJqcJK62R5TOnyOLbvjewOXAMfavrPiIab0NSUT7yjgJNuv19w/HzGF90gpQbQUUdB1d9sfVDPa1B4yIaKBTGhfUglMCxDtAuYq/W1OBE61fWfuZUr1RlIPIkX8FuAtSfOUtHCAt21fWALTVsRMQL8MTI0ng1MDKfPya0s6RtJSknqU/kwDgPdsDwH+DRxge0BOf6R6VCo53EskPjzDl1f88wDPS1pT0jTE/qZjSrHiPMlqMDmt1wBqilmuAVwEPA1MT6SOP0a0Wx9c5RhTao2a5IfVgfuAp22vWB7rDwy2fUG53a3UgUwNKINTJyZpBtsflq+XJnrVHGV7sKTdiAymh4FbbH8gqYvtbEmd6lLtlXzJzFsE2BFYA9gS6G77/fJ41yxG3NhyWq+TKgkOj0s6vNw1J9H5cycA21cADwAbEdXGu2VgSvWq5oppI0l9gWOB/xBp408B1xNZp5STrAxMDS6DUydl+zNgV+Cnkv7P9l3AXsCikg4tz7mS2C3/aE5/pHpWAtM6wIXA68BKwKXAPLYPBd4ABpTEiJzuaQI5rdfJlW6efwWOLhtqNwL2J1Jtz6p2dCl9s5qrpjOB91uOW0nnAQvb3lLSFMCitp+rcqyp4+SVUydn+1FgY+Csmiuo3wFrS+qZWUyp3tVkjL4IzFyq42P7MGAqSfPZHpuBqblkhYgGUPZ8bAzcWtaWLpL0qO33qh5bSpPhBaAPsJ6kJ4DpgNmJyhCpyeS0XgORtCpwN7AEMCT3MKV6U5tlJ2kK22NrU8JLYddtiKricwFn2h5Q2YBTZTI4NZja9PKU6omkbsDewG1EbbxdiOriYyT1BK4AtuXL5YZpbf83N4s3p5zWazwfQRa/TPWnBKFXiIrirwCblPumBU4DbrU9tOZb/le+L4/jJpRXTimldleTkTcVMJDYIN7b9gslAWIB20/WPrfC4aY6kNl6KaV2VwLTcsDaxJrS7sA/Ja1nezjwqaSpW55b2UBT3chpvZRSR1mHKNY6he0bS/HWWyQdA+xLBKx/VTi+VEcyOKWU2pWkuW2/ZfvXkkYD+5epuz9JGkGU2DrS9r+qHWmqJxmcUkrtRtJcwGmSBtnuV/bgdQXOkTRlad1yW5bXSuPLhIiUUpuRtCCwGTCCKEV0q6S9gBWJGo+Xl+fdAXwG7J2bxdOE5JVTSqlNSFqSyMS7FRgN7CLpYuAaYAywZkkbfwAYBfwiA1OamLxySil9Z5JmAG4GLrN9WblvXuAPwP3EPqYtgH2A+YETbN9c0XBTJ5BXTimltvAZ8BrwF4hmgbaHSNqbaHj5rO0biOy8eWy/mfuZ0qTkPqeUUlvoQawrrQtge1RJeHiD6NG0UMsTbb9Z/p+BKU1UBqeU0ndmexjwa2C7stkWvqwmbiJ4pdRqGZxSSm3lBuBtYh/TBrY/l7Q60fzy/mqHljqbTIhIKbUZSXMAOwIHAo8S7VtOsX1TpQNLnU4Gp5RSm5M0Z/myu+1XM/khTa4MTimllOpOrjmllFKqOxmcUkop1Z0MTimllOpOBqeUUkp1J4NTSimlupPBKaWUUt3J4JRSSqnu/D/yEyQ8WQQgUQAAAABJRU5ErkJggg==\n"
          },
          "metadata": {
            "needs_background": "light"
          }
        }
      ]
    },
    {
      "cell_type": "markdown",
      "source": [
        "#5.) Write an observation/conclusion about the graphs from Q4 and Q3"
      ],
      "metadata": {
        "id": "bK_jyyEEtTUB"
      }
    },
    {
      "cell_type": "markdown",
      "source": [
        "- For the bar charts in question 3, we can see that for in-sample accuracy, our model performed very similarly in terms of accuracy to the random walk. However, for out-of-sample accuracy, we can see that our model performed very poorly compared to the random walk. This can be seen by discrepancy between the bars for out of sample accuracy, as the bar for the model is nonexistent. This illustrates that our model did not outperform the random walk.\n"
      ],
      "metadata": {
        "id": "7kMyRptMthri"
      }
    },
    {
      "cell_type": "markdown",
      "source": [
        "# 6.) Create a parameter for number of lags in your input layer. Do a 3-fold CV to test three different time lags. i.e. Tested using 5,10,20 days of previous price data to forecast"
      ],
      "metadata": {
        "id": "pFtrp-lmtw6t"
      }
    },
    {
      "cell_type": "code",
      "source": [
        "from sklearn.model_selection import GridSearchCV\n",
        "from keras.wrappers.scikit_learn import KerasClassifier\n",
        "from keras.wrappers.scikit_learn import KerasRegressor\n",
        "from sklearn.model_selection import KFold"
      ],
      "metadata": {
        "id": "xq7CcXyzKNyl"
      },
      "execution_count": null,
      "outputs": []
    },
    {
      "cell_type": "code",
      "source": [
        "def create_model(lag):\n",
        "    model = Sequential()\n",
        "    model.add(LSTM(50, return_sequences=True, input_shape=(lag, 1)))\n",
        "    model.add(Dropout(0.2))\n",
        "\n",
        "    model.add(LSTM(50))\n",
        "    model.add(Dropout(0.2))\n",
        "\n",
        "    model.add(Dense(1, activation='sigmoid'))\n",
        "\n",
        "    model.compile(optimizer='adam', loss='binary_crossentropy', metrics=['accuracy'])\n",
        "    return(model)"
      ],
      "metadata": {
        "id": "a0c-QqnFKbfJ"
      },
      "execution_count": null,
      "outputs": []
    },
    {
      "cell_type": "code",
      "source": [
        "param_grid = {'batch_size': [10, 20, 32],\n",
        "              'epochs': [10, 20],\n",
        "              'lag': [5, 10, 20]}"
      ],
      "metadata": {
        "id": "EAeoAIzdKs71"
      },
      "execution_count": null,
      "outputs": []
    },
    {
      "cell_type": "code",
      "source": [
        "model = KerasRegressor(build_fn=create_model, verbose=0)"
      ],
      "metadata": {
        "colab": {
          "base_uri": "https://localhost:8080/"
        },
        "id": "HzunOw-pKy4Q",
        "outputId": "b91dfda7-7f89-4ed6-8dce-755b89713b34"
      },
      "execution_count": null,
      "outputs": [
        {
          "output_type": "stream",
          "name": "stderr",
          "text": [
            "<ipython-input-22-9f3192b984b9>:2: DeprecationWarning: KerasRegressor is deprecated, use Sci-Keras (https://github.com/adriangb/scikeras) instead. See https://www.adriangb.com/scikeras/stable/migration.html for help migrating.\n",
            "  model = KerasRegressor(build_fn=create_model, verbose=0)\n"
          ]
        }
      ]
    },
    {
      "cell_type": "code",
      "source": [
        "# This code performs the grid search over the hyperparameters using 3-fold cross-validation\n",
        "kfold = KFold(n_splits=3, shuffle=True, random_state=42)\n",
        "grid = GridSearchCV(estimator=model, param_grid=param_grid, n_jobs=-1, cv=kfold)\n",
        "grid_result = grid.fit(x_train, y_train)\n",
        "print(\"Best: %f using %s\" % (grid_result.best_score_, grid_result.best_params_))\n"
      ],
      "metadata": {
        "colab": {
          "base_uri": "https://localhost:8080/"
        },
        "id": "8_ufLdtFKCCk",
        "outputId": "5d2df5b9-91f5-4a39-ccd6-78647fe8aede"
      },
      "execution_count": null,
      "outputs": [
        {
          "output_type": "stream",
          "name": "stderr",
          "text": [
            "/usr/local/lib/python3.8/dist-packages/joblib/externals/loky/process_executor.py:700: UserWarning: A worker stopped while some jobs were given to the executor. This can be caused by a too short worker timeout or by a memory leak.\n",
            "  warnings.warn(\n",
            "/usr/local/lib/python3.8/dist-packages/sklearn/model_selection/_validation.py:372: FitFailedWarning: \n",
            "36 fits failed out of a total of 54.\n",
            "The score on these train-test partitions for these parameters will be set to nan.\n",
            "If these failures are not expected, you can try to debug them by setting error_score='raise'.\n",
            "\n",
            "Below are more details about the failures:\n",
            "--------------------------------------------------------------------------------\n",
            "1 fits failed with the following error:\n",
            "Traceback (most recent call last):\n",
            "  File \"/usr/local/lib/python3.8/dist-packages/sklearn/model_selection/_validation.py\", line 680, in _fit_and_score\n",
            "    estimator.fit(X_train, y_train, **fit_params)\n",
            "  File \"/usr/local/lib/python3.8/dist-packages/keras/wrappers/scikit_learn.py\", line 175, in fit\n",
            "    history = self.model.fit(x, y, **fit_args)\n",
            "  File \"/usr/local/lib/python3.8/dist-packages/keras/utils/traceback_utils.py\", line 70, in error_handler\n",
            "    raise e.with_traceback(filtered_tb) from None\n",
            "  File \"/tmp/__autograph_generated_fileog4uoxeb.py\", line 15, in tf__train_function\n",
            "    retval_ = ag__.converted_call(ag__.ld(step_function), (ag__.ld(self), ag__.ld(iterator)), None, fscope)\n",
            "ValueError: in user code:\n",
            "\n",
            "    File \"/usr/local/lib/python3.8/dist-packages/keras/engine/training.py\", line 1249, in train_function  *\n",
            "        return step_function(self, iterator)\n",
            "    File \"/usr/local/lib/python3.8/dist-packages/keras/engine/training.py\", line 1233, in step_function  **\n",
            "        outputs = model.distribute_strategy.run(run_step, args=(data,))\n",
            "    File \"/usr/local/lib/python3.8/dist-packages/keras/engine/training.py\", line 1222, in run_step  **\n",
            "        outputs = model.train_step(data)\n",
            "    File \"/usr/local/lib/python3.8/dist-packages/keras/engine/training.py\", line 1023, in train_step\n",
            "        y_pred = self(x, training=True)\n",
            "    File \"/usr/local/lib/python3.8/dist-packages/keras/utils/traceback_utils.py\", line 70, in error_handler\n",
            "        raise e.with_traceback(filtered_tb) from None\n",
            "    File \"/usr/local/lib/python3.8/dist-packages/keras/engine/input_spec.py\", line 295, in assert_input_compatibility\n",
            "        raise ValueError(\n",
            "\n",
            "    ValueError: Input 0 of layer \"sequential\" is incompatible with the layer: expected shape=(None, 5, 1), found shape=(None, 10, 1)\n",
            "\n",
            "\n",
            "--------------------------------------------------------------------------------\n",
            "1 fits failed with the following error:\n",
            "Traceback (most recent call last):\n",
            "  File \"/usr/local/lib/python3.8/dist-packages/sklearn/model_selection/_validation.py\", line 680, in _fit_and_score\n",
            "    estimator.fit(X_train, y_train, **fit_params)\n",
            "  File \"/usr/local/lib/python3.8/dist-packages/keras/wrappers/scikit_learn.py\", line 175, in fit\n",
            "    history = self.model.fit(x, y, **fit_args)\n",
            "  File \"/usr/local/lib/python3.8/dist-packages/keras/utils/traceback_utils.py\", line 70, in error_handler\n",
            "    raise e.with_traceback(filtered_tb) from None\n",
            "  File \"/tmp/__autograph_generated_filelq5zkci3.py\", line 15, in tf__train_function\n",
            "    retval_ = ag__.converted_call(ag__.ld(step_function), (ag__.ld(self), ag__.ld(iterator)), None, fscope)\n",
            "ValueError: in user code:\n",
            "\n",
            "    File \"/usr/local/lib/python3.8/dist-packages/keras/engine/training.py\", line 1249, in train_function  *\n",
            "        return step_function(self, iterator)\n",
            "    File \"/usr/local/lib/python3.8/dist-packages/keras/engine/training.py\", line 1233, in step_function  **\n",
            "        outputs = model.distribute_strategy.run(run_step, args=(data,))\n",
            "    File \"/usr/local/lib/python3.8/dist-packages/keras/engine/training.py\", line 1222, in run_step  **\n",
            "        outputs = model.train_step(data)\n",
            "    File \"/usr/local/lib/python3.8/dist-packages/keras/engine/training.py\", line 1023, in train_step\n",
            "        y_pred = self(x, training=True)\n",
            "    File \"/usr/local/lib/python3.8/dist-packages/keras/utils/traceback_utils.py\", line 70, in error_handler\n",
            "        raise e.with_traceback(filtered_tb) from None\n",
            "    File \"/usr/local/lib/python3.8/dist-packages/keras/engine/input_spec.py\", line 295, in assert_input_compatibility\n",
            "        raise ValueError(\n",
            "\n",
            "    ValueError: Input 0 of layer \"sequential\" is incompatible with the layer: expected shape=(None, 5, 1), found shape=(None, 10, 1)\n",
            "\n",
            "\n",
            "--------------------------------------------------------------------------------\n",
            "1 fits failed with the following error:\n",
            "Traceback (most recent call last):\n",
            "  File \"/usr/local/lib/python3.8/dist-packages/sklearn/model_selection/_validation.py\", line 680, in _fit_and_score\n",
            "    estimator.fit(X_train, y_train, **fit_params)\n",
            "  File \"/usr/local/lib/python3.8/dist-packages/keras/wrappers/scikit_learn.py\", line 175, in fit\n",
            "    history = self.model.fit(x, y, **fit_args)\n",
            "  File \"/usr/local/lib/python3.8/dist-packages/keras/utils/traceback_utils.py\", line 70, in error_handler\n",
            "    raise e.with_traceback(filtered_tb) from None\n",
            "  File \"/tmp/__autograph_generated_fileog4uoxeb.py\", line 15, in tf__train_function\n",
            "    retval_ = ag__.converted_call(ag__.ld(step_function), (ag__.ld(self), ag__.ld(iterator)), None, fscope)\n",
            "ValueError: in user code:\n",
            "\n",
            "    File \"/usr/local/lib/python3.8/dist-packages/keras/engine/training.py\", line 1249, in train_function  *\n",
            "        return step_function(self, iterator)\n",
            "    File \"/usr/local/lib/python3.8/dist-packages/keras/engine/training.py\", line 1233, in step_function  **\n",
            "        outputs = model.distribute_strategy.run(run_step, args=(data,))\n",
            "    File \"/usr/local/lib/python3.8/dist-packages/keras/engine/training.py\", line 1222, in run_step  **\n",
            "        outputs = model.train_step(data)\n",
            "    File \"/usr/local/lib/python3.8/dist-packages/keras/engine/training.py\", line 1023, in train_step\n",
            "        y_pred = self(x, training=True)\n",
            "    File \"/usr/local/lib/python3.8/dist-packages/keras/utils/traceback_utils.py\", line 70, in error_handler\n",
            "        raise e.with_traceback(filtered_tb) from None\n",
            "    File \"/usr/local/lib/python3.8/dist-packages/keras/engine/input_spec.py\", line 295, in assert_input_compatibility\n",
            "        raise ValueError(\n",
            "\n",
            "    ValueError: Input 0 of layer \"sequential_1\" is incompatible with the layer: expected shape=(None, 5, 1), found shape=(None, 10, 1)\n",
            "\n",
            "\n",
            "--------------------------------------------------------------------------------\n",
            "1 fits failed with the following error:\n",
            "Traceback (most recent call last):\n",
            "  File \"/usr/local/lib/python3.8/dist-packages/sklearn/model_selection/_validation.py\", line 680, in _fit_and_score\n",
            "    estimator.fit(X_train, y_train, **fit_params)\n",
            "  File \"/usr/local/lib/python3.8/dist-packages/keras/wrappers/scikit_learn.py\", line 175, in fit\n",
            "    history = self.model.fit(x, y, **fit_args)\n",
            "  File \"/usr/local/lib/python3.8/dist-packages/keras/utils/traceback_utils.py\", line 70, in error_handler\n",
            "    raise e.with_traceback(filtered_tb) from None\n",
            "  File \"/tmp/__autograph_generated_filelq5zkci3.py\", line 15, in tf__train_function\n",
            "    retval_ = ag__.converted_call(ag__.ld(step_function), (ag__.ld(self), ag__.ld(iterator)), None, fscope)\n",
            "ValueError: in user code:\n",
            "\n",
            "    File \"/usr/local/lib/python3.8/dist-packages/keras/engine/training.py\", line 1249, in train_function  *\n",
            "        return step_function(self, iterator)\n",
            "    File \"/usr/local/lib/python3.8/dist-packages/keras/engine/training.py\", line 1233, in step_function  **\n",
            "        outputs = model.distribute_strategy.run(run_step, args=(data,))\n",
            "    File \"/usr/local/lib/python3.8/dist-packages/keras/engine/training.py\", line 1222, in run_step  **\n",
            "        outputs = model.train_step(data)\n",
            "    File \"/usr/local/lib/python3.8/dist-packages/keras/engine/training.py\", line 1023, in train_step\n",
            "        y_pred = self(x, training=True)\n",
            "    File \"/usr/local/lib/python3.8/dist-packages/keras/utils/traceback_utils.py\", line 70, in error_handler\n",
            "        raise e.with_traceback(filtered_tb) from None\n",
            "    File \"/usr/local/lib/python3.8/dist-packages/keras/engine/input_spec.py\", line 295, in assert_input_compatibility\n",
            "        raise ValueError(\n",
            "\n",
            "    ValueError: Input 0 of layer \"sequential_2\" is incompatible with the layer: expected shape=(None, 20, 1), found shape=(None, 10, 1)\n",
            "\n",
            "\n",
            "--------------------------------------------------------------------------------\n",
            "1 fits failed with the following error:\n",
            "Traceback (most recent call last):\n",
            "  File \"/usr/local/lib/python3.8/dist-packages/sklearn/model_selection/_validation.py\", line 680, in _fit_and_score\n",
            "    estimator.fit(X_train, y_train, **fit_params)\n",
            "  File \"/usr/local/lib/python3.8/dist-packages/keras/wrappers/scikit_learn.py\", line 175, in fit\n",
            "    history = self.model.fit(x, y, **fit_args)\n",
            "  File \"/usr/local/lib/python3.8/dist-packages/keras/utils/traceback_utils.py\", line 70, in error_handler\n",
            "    raise e.with_traceback(filtered_tb) from None\n",
            "  File \"/tmp/__autograph_generated_filelq5zkci3.py\", line 15, in tf__train_function\n",
            "    retval_ = ag__.converted_call(ag__.ld(step_function), (ag__.ld(self), ag__.ld(iterator)), None, fscope)\n",
            "ValueError: in user code:\n",
            "\n",
            "    File \"/usr/local/lib/python3.8/dist-packages/keras/engine/training.py\", line 1249, in train_function  *\n",
            "        return step_function(self, iterator)\n",
            "    File \"/usr/local/lib/python3.8/dist-packages/keras/engine/training.py\", line 1233, in step_function  **\n",
            "        outputs = model.distribute_strategy.run(run_step, args=(data,))\n",
            "    File \"/usr/local/lib/python3.8/dist-packages/keras/engine/training.py\", line 1222, in run_step  **\n",
            "        outputs = model.train_step(data)\n",
            "    File \"/usr/local/lib/python3.8/dist-packages/keras/engine/training.py\", line 1023, in train_step\n",
            "        y_pred = self(x, training=True)\n",
            "    File \"/usr/local/lib/python3.8/dist-packages/keras/utils/traceback_utils.py\", line 70, in error_handler\n",
            "        raise e.with_traceback(filtered_tb) from None\n",
            "    File \"/usr/local/lib/python3.8/dist-packages/keras/engine/input_spec.py\", line 295, in assert_input_compatibility\n",
            "        raise ValueError(\n",
            "\n",
            "    ValueError: Input 0 of layer \"sequential_3\" is incompatible with the layer: expected shape=(None, 20, 1), found shape=(None, 10, 1)\n",
            "\n",
            "\n",
            "--------------------------------------------------------------------------------\n",
            "1 fits failed with the following error:\n",
            "Traceback (most recent call last):\n",
            "  File \"/usr/local/lib/python3.8/dist-packages/sklearn/model_selection/_validation.py\", line 680, in _fit_and_score\n",
            "    estimator.fit(X_train, y_train, **fit_params)\n",
            "  File \"/usr/local/lib/python3.8/dist-packages/keras/wrappers/scikit_learn.py\", line 175, in fit\n",
            "    history = self.model.fit(x, y, **fit_args)\n",
            "  File \"/usr/local/lib/python3.8/dist-packages/keras/utils/traceback_utils.py\", line 70, in error_handler\n",
            "    raise e.with_traceback(filtered_tb) from None\n",
            "  File \"/tmp/__autograph_generated_filelq5zkci3.py\", line 15, in tf__train_function\n",
            "    retval_ = ag__.converted_call(ag__.ld(step_function), (ag__.ld(self), ag__.ld(iterator)), None, fscope)\n",
            "ValueError: in user code:\n",
            "\n",
            "    File \"/usr/local/lib/python3.8/dist-packages/keras/engine/training.py\", line 1249, in train_function  *\n",
            "        return step_function(self, iterator)\n",
            "    File \"/usr/local/lib/python3.8/dist-packages/keras/engine/training.py\", line 1233, in step_function  **\n",
            "        outputs = model.distribute_strategy.run(run_step, args=(data,))\n",
            "    File \"/usr/local/lib/python3.8/dist-packages/keras/engine/training.py\", line 1222, in run_step  **\n",
            "        outputs = model.train_step(data)\n",
            "    File \"/usr/local/lib/python3.8/dist-packages/keras/engine/training.py\", line 1023, in train_step\n",
            "        y_pred = self(x, training=True)\n",
            "    File \"/usr/local/lib/python3.8/dist-packages/keras/utils/traceback_utils.py\", line 70, in error_handler\n",
            "        raise e.with_traceback(filtered_tb) from None\n",
            "    File \"/usr/local/lib/python3.8/dist-packages/keras/engine/input_spec.py\", line 295, in assert_input_compatibility\n",
            "        raise ValueError(\n",
            "\n",
            "    ValueError: Input 0 of layer \"sequential_4\" is incompatible with the layer: expected shape=(None, 20, 1), found shape=(None, 10, 1)\n",
            "\n",
            "\n",
            "--------------------------------------------------------------------------------\n",
            "1 fits failed with the following error:\n",
            "Traceback (most recent call last):\n",
            "  File \"/usr/local/lib/python3.8/dist-packages/sklearn/model_selection/_validation.py\", line 680, in _fit_and_score\n",
            "    estimator.fit(X_train, y_train, **fit_params)\n",
            "  File \"/usr/local/lib/python3.8/dist-packages/keras/wrappers/scikit_learn.py\", line 175, in fit\n",
            "    history = self.model.fit(x, y, **fit_args)\n",
            "  File \"/usr/local/lib/python3.8/dist-packages/keras/utils/traceback_utils.py\", line 70, in error_handler\n",
            "    raise e.with_traceback(filtered_tb) from None\n",
            "  File \"/tmp/__autograph_generated_filelq5zkci3.py\", line 15, in tf__train_function\n",
            "    retval_ = ag__.converted_call(ag__.ld(step_function), (ag__.ld(self), ag__.ld(iterator)), None, fscope)\n",
            "ValueError: in user code:\n",
            "\n",
            "    File \"/usr/local/lib/python3.8/dist-packages/keras/engine/training.py\", line 1249, in train_function  *\n",
            "        return step_function(self, iterator)\n",
            "    File \"/usr/local/lib/python3.8/dist-packages/keras/engine/training.py\", line 1233, in step_function  **\n",
            "        outputs = model.distribute_strategy.run(run_step, args=(data,))\n",
            "    File \"/usr/local/lib/python3.8/dist-packages/keras/engine/training.py\", line 1222, in run_step  **\n",
            "        outputs = model.train_step(data)\n",
            "    File \"/usr/local/lib/python3.8/dist-packages/keras/engine/training.py\", line 1023, in train_step\n",
            "        y_pred = self(x, training=True)\n",
            "    File \"/usr/local/lib/python3.8/dist-packages/keras/utils/traceback_utils.py\", line 70, in error_handler\n",
            "        raise e.with_traceback(filtered_tb) from None\n",
            "    File \"/usr/local/lib/python3.8/dist-packages/keras/engine/input_spec.py\", line 295, in assert_input_compatibility\n",
            "        raise ValueError(\n",
            "\n",
            "    ValueError: Input 0 of layer \"sequential_5\" is incompatible with the layer: expected shape=(None, 5, 1), found shape=(None, 10, 1)\n",
            "\n",
            "\n",
            "--------------------------------------------------------------------------------\n",
            "1 fits failed with the following error:\n",
            "Traceback (most recent call last):\n",
            "  File \"/usr/local/lib/python3.8/dist-packages/sklearn/model_selection/_validation.py\", line 680, in _fit_and_score\n",
            "    estimator.fit(X_train, y_train, **fit_params)\n",
            "  File \"/usr/local/lib/python3.8/dist-packages/keras/wrappers/scikit_learn.py\", line 175, in fit\n",
            "    history = self.model.fit(x, y, **fit_args)\n",
            "  File \"/usr/local/lib/python3.8/dist-packages/keras/utils/traceback_utils.py\", line 70, in error_handler\n",
            "    raise e.with_traceback(filtered_tb) from None\n",
            "  File \"/tmp/__autograph_generated_filelq5zkci3.py\", line 15, in tf__train_function\n",
            "    retval_ = ag__.converted_call(ag__.ld(step_function), (ag__.ld(self), ag__.ld(iterator)), None, fscope)\n",
            "ValueError: in user code:\n",
            "\n",
            "    File \"/usr/local/lib/python3.8/dist-packages/keras/engine/training.py\", line 1249, in train_function  *\n",
            "        return step_function(self, iterator)\n",
            "    File \"/usr/local/lib/python3.8/dist-packages/keras/engine/training.py\", line 1233, in step_function  **\n",
            "        outputs = model.distribute_strategy.run(run_step, args=(data,))\n",
            "    File \"/usr/local/lib/python3.8/dist-packages/keras/engine/training.py\", line 1222, in run_step  **\n",
            "        outputs = model.train_step(data)\n",
            "    File \"/usr/local/lib/python3.8/dist-packages/keras/engine/training.py\", line 1023, in train_step\n",
            "        y_pred = self(x, training=True)\n",
            "    File \"/usr/local/lib/python3.8/dist-packages/keras/utils/traceback_utils.py\", line 70, in error_handler\n",
            "        raise e.with_traceback(filtered_tb) from None\n",
            "    File \"/usr/local/lib/python3.8/dist-packages/keras/engine/input_spec.py\", line 295, in assert_input_compatibility\n",
            "        raise ValueError(\n",
            "\n",
            "    ValueError: Input 0 of layer \"sequential_6\" is incompatible with the layer: expected shape=(None, 5, 1), found shape=(None, 10, 1)\n",
            "\n",
            "\n",
            "--------------------------------------------------------------------------------\n",
            "1 fits failed with the following error:\n",
            "Traceback (most recent call last):\n",
            "  File \"/usr/local/lib/python3.8/dist-packages/sklearn/model_selection/_validation.py\", line 680, in _fit_and_score\n",
            "    estimator.fit(X_train, y_train, **fit_params)\n",
            "  File \"/usr/local/lib/python3.8/dist-packages/keras/wrappers/scikit_learn.py\", line 175, in fit\n",
            "    history = self.model.fit(x, y, **fit_args)\n",
            "  File \"/usr/local/lib/python3.8/dist-packages/keras/utils/traceback_utils.py\", line 70, in error_handler\n",
            "    raise e.with_traceback(filtered_tb) from None\n",
            "  File \"/tmp/__autograph_generated_filelq5zkci3.py\", line 15, in tf__train_function\n",
            "    retval_ = ag__.converted_call(ag__.ld(step_function), (ag__.ld(self), ag__.ld(iterator)), None, fscope)\n",
            "ValueError: in user code:\n",
            "\n",
            "    File \"/usr/local/lib/python3.8/dist-packages/keras/engine/training.py\", line 1249, in train_function  *\n",
            "        return step_function(self, iterator)\n",
            "    File \"/usr/local/lib/python3.8/dist-packages/keras/engine/training.py\", line 1233, in step_function  **\n",
            "        outputs = model.distribute_strategy.run(run_step, args=(data,))\n",
            "    File \"/usr/local/lib/python3.8/dist-packages/keras/engine/training.py\", line 1222, in run_step  **\n",
            "        outputs = model.train_step(data)\n",
            "    File \"/usr/local/lib/python3.8/dist-packages/keras/engine/training.py\", line 1023, in train_step\n",
            "        y_pred = self(x, training=True)\n",
            "    File \"/usr/local/lib/python3.8/dist-packages/keras/utils/traceback_utils.py\", line 70, in error_handler\n",
            "        raise e.with_traceback(filtered_tb) from None\n",
            "    File \"/usr/local/lib/python3.8/dist-packages/keras/engine/input_spec.py\", line 295, in assert_input_compatibility\n",
            "        raise ValueError(\n",
            "\n",
            "    ValueError: Input 0 of layer \"sequential_7\" is incompatible with the layer: expected shape=(None, 5, 1), found shape=(None, 10, 1)\n",
            "\n",
            "\n",
            "--------------------------------------------------------------------------------\n",
            "1 fits failed with the following error:\n",
            "Traceback (most recent call last):\n",
            "  File \"/usr/local/lib/python3.8/dist-packages/sklearn/model_selection/_validation.py\", line 680, in _fit_and_score\n",
            "    estimator.fit(X_train, y_train, **fit_params)\n",
            "  File \"/usr/local/lib/python3.8/dist-packages/keras/wrappers/scikit_learn.py\", line 175, in fit\n",
            "    history = self.model.fit(x, y, **fit_args)\n",
            "  File \"/usr/local/lib/python3.8/dist-packages/keras/utils/traceback_utils.py\", line 70, in error_handler\n",
            "    raise e.with_traceback(filtered_tb) from None\n",
            "  File \"/tmp/__autograph_generated_files6crof1j.py\", line 15, in tf__train_function\n",
            "    retval_ = ag__.converted_call(ag__.ld(step_function), (ag__.ld(self), ag__.ld(iterator)), None, fscope)\n",
            "ValueError: in user code:\n",
            "\n",
            "    File \"/usr/local/lib/python3.8/dist-packages/keras/engine/training.py\", line 1249, in train_function  *\n",
            "        return step_function(self, iterator)\n",
            "    File \"/usr/local/lib/python3.8/dist-packages/keras/engine/training.py\", line 1233, in step_function  **\n",
            "        outputs = model.distribute_strategy.run(run_step, args=(data,))\n",
            "    File \"/usr/local/lib/python3.8/dist-packages/keras/engine/training.py\", line 1222, in run_step  **\n",
            "        outputs = model.train_step(data)\n",
            "    File \"/usr/local/lib/python3.8/dist-packages/keras/engine/training.py\", line 1023, in train_step\n",
            "        y_pred = self(x, training=True)\n",
            "    File \"/usr/local/lib/python3.8/dist-packages/keras/utils/traceback_utils.py\", line 70, in error_handler\n",
            "        raise e.with_traceback(filtered_tb) from None\n",
            "    File \"/usr/local/lib/python3.8/dist-packages/keras/engine/input_spec.py\", line 295, in assert_input_compatibility\n",
            "        raise ValueError(\n",
            "\n",
            "    ValueError: Input 0 of layer \"sequential\" is incompatible with the layer: expected shape=(None, 20, 1), found shape=(None, 10, 1)\n",
            "\n",
            "\n",
            "--------------------------------------------------------------------------------\n",
            "1 fits failed with the following error:\n",
            "Traceback (most recent call last):\n",
            "  File \"/usr/local/lib/python3.8/dist-packages/sklearn/model_selection/_validation.py\", line 680, in _fit_and_score\n",
            "    estimator.fit(X_train, y_train, **fit_params)\n",
            "  File \"/usr/local/lib/python3.8/dist-packages/keras/wrappers/scikit_learn.py\", line 175, in fit\n",
            "    history = self.model.fit(x, y, **fit_args)\n",
            "  File \"/usr/local/lib/python3.8/dist-packages/keras/utils/traceback_utils.py\", line 70, in error_handler\n",
            "    raise e.with_traceback(filtered_tb) from None\n",
            "  File \"/tmp/__autograph_generated_files6crof1j.py\", line 15, in tf__train_function\n",
            "    retval_ = ag__.converted_call(ag__.ld(step_function), (ag__.ld(self), ag__.ld(iterator)), None, fscope)\n",
            "ValueError: in user code:\n",
            "\n",
            "    File \"/usr/local/lib/python3.8/dist-packages/keras/engine/training.py\", line 1249, in train_function  *\n",
            "        return step_function(self, iterator)\n",
            "    File \"/usr/local/lib/python3.8/dist-packages/keras/engine/training.py\", line 1233, in step_function  **\n",
            "        outputs = model.distribute_strategy.run(run_step, args=(data,))\n",
            "    File \"/usr/local/lib/python3.8/dist-packages/keras/engine/training.py\", line 1222, in run_step  **\n",
            "        outputs = model.train_step(data)\n",
            "    File \"/usr/local/lib/python3.8/dist-packages/keras/engine/training.py\", line 1023, in train_step\n",
            "        y_pred = self(x, training=True)\n",
            "    File \"/usr/local/lib/python3.8/dist-packages/keras/utils/traceback_utils.py\", line 70, in error_handler\n",
            "        raise e.with_traceback(filtered_tb) from None\n",
            "    File \"/usr/local/lib/python3.8/dist-packages/keras/engine/input_spec.py\", line 295, in assert_input_compatibility\n",
            "        raise ValueError(\n",
            "\n",
            "    ValueError: Input 0 of layer \"sequential_1\" is incompatible with the layer: expected shape=(None, 20, 1), found shape=(None, 10, 1)\n",
            "\n",
            "\n",
            "--------------------------------------------------------------------------------\n",
            "1 fits failed with the following error:\n",
            "Traceback (most recent call last):\n",
            "  File \"/usr/local/lib/python3.8/dist-packages/sklearn/model_selection/_validation.py\", line 680, in _fit_and_score\n",
            "    estimator.fit(X_train, y_train, **fit_params)\n",
            "  File \"/usr/local/lib/python3.8/dist-packages/keras/wrappers/scikit_learn.py\", line 175, in fit\n",
            "    history = self.model.fit(x, y, **fit_args)\n",
            "  File \"/usr/local/lib/python3.8/dist-packages/keras/utils/traceback_utils.py\", line 70, in error_handler\n",
            "    raise e.with_traceback(filtered_tb) from None\n",
            "  File \"/tmp/__autograph_generated_files6crof1j.py\", line 15, in tf__train_function\n",
            "    retval_ = ag__.converted_call(ag__.ld(step_function), (ag__.ld(self), ag__.ld(iterator)), None, fscope)\n",
            "ValueError: in user code:\n",
            "\n",
            "    File \"/usr/local/lib/python3.8/dist-packages/keras/engine/training.py\", line 1249, in train_function  *\n",
            "        return step_function(self, iterator)\n",
            "    File \"/usr/local/lib/python3.8/dist-packages/keras/engine/training.py\", line 1233, in step_function  **\n",
            "        outputs = model.distribute_strategy.run(run_step, args=(data,))\n",
            "    File \"/usr/local/lib/python3.8/dist-packages/keras/engine/training.py\", line 1222, in run_step  **\n",
            "        outputs = model.train_step(data)\n",
            "    File \"/usr/local/lib/python3.8/dist-packages/keras/engine/training.py\", line 1023, in train_step\n",
            "        y_pred = self(x, training=True)\n",
            "    File \"/usr/local/lib/python3.8/dist-packages/keras/utils/traceback_utils.py\", line 70, in error_handler\n",
            "        raise e.with_traceback(filtered_tb) from None\n",
            "    File \"/usr/local/lib/python3.8/dist-packages/keras/engine/input_spec.py\", line 295, in assert_input_compatibility\n",
            "        raise ValueError(\n",
            "\n",
            "    ValueError: Input 0 of layer \"sequential_2\" is incompatible with the layer: expected shape=(None, 20, 1), found shape=(None, 10, 1)\n",
            "\n",
            "\n",
            "--------------------------------------------------------------------------------\n",
            "1 fits failed with the following error:\n",
            "Traceback (most recent call last):\n",
            "  File \"/usr/local/lib/python3.8/dist-packages/sklearn/model_selection/_validation.py\", line 680, in _fit_and_score\n",
            "    estimator.fit(X_train, y_train, **fit_params)\n",
            "  File \"/usr/local/lib/python3.8/dist-packages/keras/wrappers/scikit_learn.py\", line 175, in fit\n",
            "    history = self.model.fit(x, y, **fit_args)\n",
            "  File \"/usr/local/lib/python3.8/dist-packages/keras/utils/traceback_utils.py\", line 70, in error_handler\n",
            "    raise e.with_traceback(filtered_tb) from None\n",
            "  File \"/tmp/__autograph_generated_files6crof1j.py\", line 15, in tf__train_function\n",
            "    retval_ = ag__.converted_call(ag__.ld(step_function), (ag__.ld(self), ag__.ld(iterator)), None, fscope)\n",
            "ValueError: in user code:\n",
            "\n",
            "    File \"/usr/local/lib/python3.8/dist-packages/keras/engine/training.py\", line 1249, in train_function  *\n",
            "        return step_function(self, iterator)\n",
            "    File \"/usr/local/lib/python3.8/dist-packages/keras/engine/training.py\", line 1233, in step_function  **\n",
            "        outputs = model.distribute_strategy.run(run_step, args=(data,))\n",
            "    File \"/usr/local/lib/python3.8/dist-packages/keras/engine/training.py\", line 1222, in run_step  **\n",
            "        outputs = model.train_step(data)\n",
            "    File \"/usr/local/lib/python3.8/dist-packages/keras/engine/training.py\", line 1023, in train_step\n",
            "        y_pred = self(x, training=True)\n",
            "    File \"/usr/local/lib/python3.8/dist-packages/keras/utils/traceback_utils.py\", line 70, in error_handler\n",
            "        raise e.with_traceback(filtered_tb) from None\n",
            "    File \"/usr/local/lib/python3.8/dist-packages/keras/engine/input_spec.py\", line 295, in assert_input_compatibility\n",
            "        raise ValueError(\n",
            "\n",
            "    ValueError: Input 0 of layer \"sequential_3\" is incompatible with the layer: expected shape=(None, 5, 1), found shape=(None, 10, 1)\n",
            "\n",
            "\n",
            "--------------------------------------------------------------------------------\n",
            "1 fits failed with the following error:\n",
            "Traceback (most recent call last):\n",
            "  File \"/usr/local/lib/python3.8/dist-packages/sklearn/model_selection/_validation.py\", line 680, in _fit_and_score\n",
            "    estimator.fit(X_train, y_train, **fit_params)\n",
            "  File \"/usr/local/lib/python3.8/dist-packages/keras/wrappers/scikit_learn.py\", line 175, in fit\n",
            "    history = self.model.fit(x, y, **fit_args)\n",
            "  File \"/usr/local/lib/python3.8/dist-packages/keras/utils/traceback_utils.py\", line 70, in error_handler\n",
            "    raise e.with_traceback(filtered_tb) from None\n",
            "  File \"/tmp/__autograph_generated_files6crof1j.py\", line 15, in tf__train_function\n",
            "    retval_ = ag__.converted_call(ag__.ld(step_function), (ag__.ld(self), ag__.ld(iterator)), None, fscope)\n",
            "ValueError: in user code:\n",
            "\n",
            "    File \"/usr/local/lib/python3.8/dist-packages/keras/engine/training.py\", line 1249, in train_function  *\n",
            "        return step_function(self, iterator)\n",
            "    File \"/usr/local/lib/python3.8/dist-packages/keras/engine/training.py\", line 1233, in step_function  **\n",
            "        outputs = model.distribute_strategy.run(run_step, args=(data,))\n",
            "    File \"/usr/local/lib/python3.8/dist-packages/keras/engine/training.py\", line 1222, in run_step  **\n",
            "        outputs = model.train_step(data)\n",
            "    File \"/usr/local/lib/python3.8/dist-packages/keras/engine/training.py\", line 1023, in train_step\n",
            "        y_pred = self(x, training=True)\n",
            "    File \"/usr/local/lib/python3.8/dist-packages/keras/utils/traceback_utils.py\", line 70, in error_handler\n",
            "        raise e.with_traceback(filtered_tb) from None\n",
            "    File \"/usr/local/lib/python3.8/dist-packages/keras/engine/input_spec.py\", line 295, in assert_input_compatibility\n",
            "        raise ValueError(\n",
            "\n",
            "    ValueError: Input 0 of layer \"sequential_4\" is incompatible with the layer: expected shape=(None, 5, 1), found shape=(None, 10, 1)\n",
            "\n",
            "\n",
            "--------------------------------------------------------------------------------\n",
            "1 fits failed with the following error:\n",
            "Traceback (most recent call last):\n",
            "  File \"/usr/local/lib/python3.8/dist-packages/sklearn/model_selection/_validation.py\", line 680, in _fit_and_score\n",
            "    estimator.fit(X_train, y_train, **fit_params)\n",
            "  File \"/usr/local/lib/python3.8/dist-packages/keras/wrappers/scikit_learn.py\", line 175, in fit\n",
            "    history = self.model.fit(x, y, **fit_args)\n",
            "  File \"/usr/local/lib/python3.8/dist-packages/keras/utils/traceback_utils.py\", line 70, in error_handler\n",
            "    raise e.with_traceback(filtered_tb) from None\n",
            "  File \"/tmp/__autograph_generated_files6crof1j.py\", line 15, in tf__train_function\n",
            "    retval_ = ag__.converted_call(ag__.ld(step_function), (ag__.ld(self), ag__.ld(iterator)), None, fscope)\n",
            "ValueError: in user code:\n",
            "\n",
            "    File \"/usr/local/lib/python3.8/dist-packages/keras/engine/training.py\", line 1249, in train_function  *\n",
            "        return step_function(self, iterator)\n",
            "    File \"/usr/local/lib/python3.8/dist-packages/keras/engine/training.py\", line 1233, in step_function  **\n",
            "        outputs = model.distribute_strategy.run(run_step, args=(data,))\n",
            "    File \"/usr/local/lib/python3.8/dist-packages/keras/engine/training.py\", line 1222, in run_step  **\n",
            "        outputs = model.train_step(data)\n",
            "    File \"/usr/local/lib/python3.8/dist-packages/keras/engine/training.py\", line 1023, in train_step\n",
            "        y_pred = self(x, training=True)\n",
            "    File \"/usr/local/lib/python3.8/dist-packages/keras/utils/traceback_utils.py\", line 70, in error_handler\n",
            "        raise e.with_traceback(filtered_tb) from None\n",
            "    File \"/usr/local/lib/python3.8/dist-packages/keras/engine/input_spec.py\", line 295, in assert_input_compatibility\n",
            "        raise ValueError(\n",
            "\n",
            "    ValueError: Input 0 of layer \"sequential_5\" is incompatible with the layer: expected shape=(None, 5, 1), found shape=(None, 10, 1)\n",
            "\n",
            "\n",
            "--------------------------------------------------------------------------------\n",
            "1 fits failed with the following error:\n",
            "Traceback (most recent call last):\n",
            "  File \"/usr/local/lib/python3.8/dist-packages/sklearn/model_selection/_validation.py\", line 680, in _fit_and_score\n",
            "    estimator.fit(X_train, y_train, **fit_params)\n",
            "  File \"/usr/local/lib/python3.8/dist-packages/keras/wrappers/scikit_learn.py\", line 175, in fit\n",
            "    history = self.model.fit(x, y, **fit_args)\n",
            "  File \"/usr/local/lib/python3.8/dist-packages/keras/utils/traceback_utils.py\", line 70, in error_handler\n",
            "    raise e.with_traceback(filtered_tb) from None\n",
            "  File \"/tmp/__autograph_generated_filexz6m_egc.py\", line 15, in tf__train_function\n",
            "    retval_ = ag__.converted_call(ag__.ld(step_function), (ag__.ld(self), ag__.ld(iterator)), None, fscope)\n",
            "ValueError: in user code:\n",
            "\n",
            "    File \"/usr/local/lib/python3.8/dist-packages/keras/engine/training.py\", line 1249, in train_function  *\n",
            "        return step_function(self, iterator)\n",
            "    File \"/usr/local/lib/python3.8/dist-packages/keras/engine/training.py\", line 1233, in step_function  **\n",
            "        outputs = model.distribute_strategy.run(run_step, args=(data,))\n",
            "    File \"/usr/local/lib/python3.8/dist-packages/keras/engine/training.py\", line 1222, in run_step  **\n",
            "        outputs = model.train_step(data)\n",
            "    File \"/usr/local/lib/python3.8/dist-packages/keras/engine/training.py\", line 1023, in train_step\n",
            "        y_pred = self(x, training=True)\n",
            "    File \"/usr/local/lib/python3.8/dist-packages/keras/utils/traceback_utils.py\", line 70, in error_handler\n",
            "        raise e.with_traceback(filtered_tb) from None\n",
            "    File \"/usr/local/lib/python3.8/dist-packages/keras/engine/input_spec.py\", line 295, in assert_input_compatibility\n",
            "        raise ValueError(\n",
            "\n",
            "    ValueError: Input 0 of layer \"sequential\" is incompatible with the layer: expected shape=(None, 20, 1), found shape=(None, 10, 1)\n",
            "\n",
            "\n",
            "--------------------------------------------------------------------------------\n",
            "1 fits failed with the following error:\n",
            "Traceback (most recent call last):\n",
            "  File \"/usr/local/lib/python3.8/dist-packages/sklearn/model_selection/_validation.py\", line 680, in _fit_and_score\n",
            "    estimator.fit(X_train, y_train, **fit_params)\n",
            "  File \"/usr/local/lib/python3.8/dist-packages/keras/wrappers/scikit_learn.py\", line 175, in fit\n",
            "    history = self.model.fit(x, y, **fit_args)\n",
            "  File \"/usr/local/lib/python3.8/dist-packages/keras/utils/traceback_utils.py\", line 70, in error_handler\n",
            "    raise e.with_traceback(filtered_tb) from None\n",
            "  File \"/tmp/__autograph_generated_filexz6m_egc.py\", line 15, in tf__train_function\n",
            "    retval_ = ag__.converted_call(ag__.ld(step_function), (ag__.ld(self), ag__.ld(iterator)), None, fscope)\n",
            "ValueError: in user code:\n",
            "\n",
            "    File \"/usr/local/lib/python3.8/dist-packages/keras/engine/training.py\", line 1249, in train_function  *\n",
            "        return step_function(self, iterator)\n",
            "    File \"/usr/local/lib/python3.8/dist-packages/keras/engine/training.py\", line 1233, in step_function  **\n",
            "        outputs = model.distribute_strategy.run(run_step, args=(data,))\n",
            "    File \"/usr/local/lib/python3.8/dist-packages/keras/engine/training.py\", line 1222, in run_step  **\n",
            "        outputs = model.train_step(data)\n",
            "    File \"/usr/local/lib/python3.8/dist-packages/keras/engine/training.py\", line 1023, in train_step\n",
            "        y_pred = self(x, training=True)\n",
            "    File \"/usr/local/lib/python3.8/dist-packages/keras/utils/traceback_utils.py\", line 70, in error_handler\n",
            "        raise e.with_traceback(filtered_tb) from None\n",
            "    File \"/usr/local/lib/python3.8/dist-packages/keras/engine/input_spec.py\", line 295, in assert_input_compatibility\n",
            "        raise ValueError(\n",
            "\n",
            "    ValueError: Input 0 of layer \"sequential_1\" is incompatible with the layer: expected shape=(None, 20, 1), found shape=(None, 10, 1)\n",
            "\n",
            "\n",
            "--------------------------------------------------------------------------------\n",
            "1 fits failed with the following error:\n",
            "Traceback (most recent call last):\n",
            "  File \"/usr/local/lib/python3.8/dist-packages/sklearn/model_selection/_validation.py\", line 680, in _fit_and_score\n",
            "    estimator.fit(X_train, y_train, **fit_params)\n",
            "  File \"/usr/local/lib/python3.8/dist-packages/keras/wrappers/scikit_learn.py\", line 175, in fit\n",
            "    history = self.model.fit(x, y, **fit_args)\n",
            "  File \"/usr/local/lib/python3.8/dist-packages/keras/utils/traceback_utils.py\", line 70, in error_handler\n",
            "    raise e.with_traceback(filtered_tb) from None\n",
            "  File \"/tmp/__autograph_generated_filexz6m_egc.py\", line 15, in tf__train_function\n",
            "    retval_ = ag__.converted_call(ag__.ld(step_function), (ag__.ld(self), ag__.ld(iterator)), None, fscope)\n",
            "ValueError: in user code:\n",
            "\n",
            "    File \"/usr/local/lib/python3.8/dist-packages/keras/engine/training.py\", line 1249, in train_function  *\n",
            "        return step_function(self, iterator)\n",
            "    File \"/usr/local/lib/python3.8/dist-packages/keras/engine/training.py\", line 1233, in step_function  **\n",
            "        outputs = model.distribute_strategy.run(run_step, args=(data,))\n",
            "    File \"/usr/local/lib/python3.8/dist-packages/keras/engine/training.py\", line 1222, in run_step  **\n",
            "        outputs = model.train_step(data)\n",
            "    File \"/usr/local/lib/python3.8/dist-packages/keras/engine/training.py\", line 1023, in train_step\n",
            "        y_pred = self(x, training=True)\n",
            "    File \"/usr/local/lib/python3.8/dist-packages/keras/utils/traceback_utils.py\", line 70, in error_handler\n",
            "        raise e.with_traceback(filtered_tb) from None\n",
            "    File \"/usr/local/lib/python3.8/dist-packages/keras/engine/input_spec.py\", line 295, in assert_input_compatibility\n",
            "        raise ValueError(\n",
            "\n",
            "    ValueError: Input 0 of layer \"sequential_2\" is incompatible with the layer: expected shape=(None, 20, 1), found shape=(None, 10, 1)\n",
            "\n",
            "\n",
            "--------------------------------------------------------------------------------\n",
            "1 fits failed with the following error:\n",
            "Traceback (most recent call last):\n",
            "  File \"/usr/local/lib/python3.8/dist-packages/sklearn/model_selection/_validation.py\", line 680, in _fit_and_score\n",
            "    estimator.fit(X_train, y_train, **fit_params)\n",
            "  File \"/usr/local/lib/python3.8/dist-packages/keras/wrappers/scikit_learn.py\", line 175, in fit\n",
            "    history = self.model.fit(x, y, **fit_args)\n",
            "  File \"/usr/local/lib/python3.8/dist-packages/keras/utils/traceback_utils.py\", line 70, in error_handler\n",
            "    raise e.with_traceback(filtered_tb) from None\n",
            "  File \"/tmp/__autograph_generated_filexz6m_egc.py\", line 15, in tf__train_function\n",
            "    retval_ = ag__.converted_call(ag__.ld(step_function), (ag__.ld(self), ag__.ld(iterator)), None, fscope)\n",
            "ValueError: in user code:\n",
            "\n",
            "    File \"/usr/local/lib/python3.8/dist-packages/keras/engine/training.py\", line 1249, in train_function  *\n",
            "        return step_function(self, iterator)\n",
            "    File \"/usr/local/lib/python3.8/dist-packages/keras/engine/training.py\", line 1233, in step_function  **\n",
            "        outputs = model.distribute_strategy.run(run_step, args=(data,))\n",
            "    File \"/usr/local/lib/python3.8/dist-packages/keras/engine/training.py\", line 1222, in run_step  **\n",
            "        outputs = model.train_step(data)\n",
            "    File \"/usr/local/lib/python3.8/dist-packages/keras/engine/training.py\", line 1023, in train_step\n",
            "        y_pred = self(x, training=True)\n",
            "    File \"/usr/local/lib/python3.8/dist-packages/keras/utils/traceback_utils.py\", line 70, in error_handler\n",
            "        raise e.with_traceback(filtered_tb) from None\n",
            "    File \"/usr/local/lib/python3.8/dist-packages/keras/engine/input_spec.py\", line 295, in assert_input_compatibility\n",
            "        raise ValueError(\n",
            "\n",
            "    ValueError: Input 0 of layer \"sequential_3\" is incompatible with the layer: expected shape=(None, 5, 1), found shape=(None, 10, 1)\n",
            "\n",
            "\n",
            "--------------------------------------------------------------------------------\n",
            "1 fits failed with the following error:\n",
            "Traceback (most recent call last):\n",
            "  File \"/usr/local/lib/python3.8/dist-packages/sklearn/model_selection/_validation.py\", line 680, in _fit_and_score\n",
            "    estimator.fit(X_train, y_train, **fit_params)\n",
            "  File \"/usr/local/lib/python3.8/dist-packages/keras/wrappers/scikit_learn.py\", line 175, in fit\n",
            "    history = self.model.fit(x, y, **fit_args)\n",
            "  File \"/usr/local/lib/python3.8/dist-packages/keras/utils/traceback_utils.py\", line 70, in error_handler\n",
            "    raise e.with_traceback(filtered_tb) from None\n",
            "  File \"/tmp/__autograph_generated_filexz6m_egc.py\", line 15, in tf__train_function\n",
            "    retval_ = ag__.converted_call(ag__.ld(step_function), (ag__.ld(self), ag__.ld(iterator)), None, fscope)\n",
            "ValueError: in user code:\n",
            "\n",
            "    File \"/usr/local/lib/python3.8/dist-packages/keras/engine/training.py\", line 1249, in train_function  *\n",
            "        return step_function(self, iterator)\n",
            "    File \"/usr/local/lib/python3.8/dist-packages/keras/engine/training.py\", line 1233, in step_function  **\n",
            "        outputs = model.distribute_strategy.run(run_step, args=(data,))\n",
            "    File \"/usr/local/lib/python3.8/dist-packages/keras/engine/training.py\", line 1222, in run_step  **\n",
            "        outputs = model.train_step(data)\n",
            "    File \"/usr/local/lib/python3.8/dist-packages/keras/engine/training.py\", line 1023, in train_step\n",
            "        y_pred = self(x, training=True)\n",
            "    File \"/usr/local/lib/python3.8/dist-packages/keras/utils/traceback_utils.py\", line 70, in error_handler\n",
            "        raise e.with_traceback(filtered_tb) from None\n",
            "    File \"/usr/local/lib/python3.8/dist-packages/keras/engine/input_spec.py\", line 295, in assert_input_compatibility\n",
            "        raise ValueError(\n",
            "\n",
            "    ValueError: Input 0 of layer \"sequential_4\" is incompatible with the layer: expected shape=(None, 5, 1), found shape=(None, 10, 1)\n",
            "\n",
            "\n",
            "--------------------------------------------------------------------------------\n",
            "1 fits failed with the following error:\n",
            "Traceback (most recent call last):\n",
            "  File \"/usr/local/lib/python3.8/dist-packages/sklearn/model_selection/_validation.py\", line 680, in _fit_and_score\n",
            "    estimator.fit(X_train, y_train, **fit_params)\n",
            "  File \"/usr/local/lib/python3.8/dist-packages/keras/wrappers/scikit_learn.py\", line 175, in fit\n",
            "    history = self.model.fit(x, y, **fit_args)\n",
            "  File \"/usr/local/lib/python3.8/dist-packages/keras/utils/traceback_utils.py\", line 70, in error_handler\n",
            "    raise e.with_traceback(filtered_tb) from None\n",
            "  File \"/tmp/__autograph_generated_filexz6m_egc.py\", line 15, in tf__train_function\n",
            "    retval_ = ag__.converted_call(ag__.ld(step_function), (ag__.ld(self), ag__.ld(iterator)), None, fscope)\n",
            "ValueError: in user code:\n",
            "\n",
            "    File \"/usr/local/lib/python3.8/dist-packages/keras/engine/training.py\", line 1249, in train_function  *\n",
            "        return step_function(self, iterator)\n",
            "    File \"/usr/local/lib/python3.8/dist-packages/keras/engine/training.py\", line 1233, in step_function  **\n",
            "        outputs = model.distribute_strategy.run(run_step, args=(data,))\n",
            "    File \"/usr/local/lib/python3.8/dist-packages/keras/engine/training.py\", line 1222, in run_step  **\n",
            "        outputs = model.train_step(data)\n",
            "    File \"/usr/local/lib/python3.8/dist-packages/keras/engine/training.py\", line 1023, in train_step\n",
            "        y_pred = self(x, training=True)\n",
            "    File \"/usr/local/lib/python3.8/dist-packages/keras/utils/traceback_utils.py\", line 70, in error_handler\n",
            "        raise e.with_traceback(filtered_tb) from None\n",
            "    File \"/usr/local/lib/python3.8/dist-packages/keras/engine/input_spec.py\", line 295, in assert_input_compatibility\n",
            "        raise ValueError(\n",
            "\n",
            "    ValueError: Input 0 of layer \"sequential_5\" is incompatible with the layer: expected shape=(None, 5, 1), found shape=(None, 10, 1)\n",
            "\n",
            "\n",
            "--------------------------------------------------------------------------------\n",
            "1 fits failed with the following error:\n",
            "Traceback (most recent call last):\n",
            "  File \"/usr/local/lib/python3.8/dist-packages/sklearn/model_selection/_validation.py\", line 680, in _fit_and_score\n",
            "    estimator.fit(X_train, y_train, **fit_params)\n",
            "  File \"/usr/local/lib/python3.8/dist-packages/keras/wrappers/scikit_learn.py\", line 175, in fit\n",
            "    history = self.model.fit(x, y, **fit_args)\n",
            "  File \"/usr/local/lib/python3.8/dist-packages/keras/utils/traceback_utils.py\", line 70, in error_handler\n",
            "    raise e.with_traceback(filtered_tb) from None\n",
            "  File \"/tmp/__autograph_generated_filefstsicun.py\", line 15, in tf__train_function\n",
            "    retval_ = ag__.converted_call(ag__.ld(step_function), (ag__.ld(self), ag__.ld(iterator)), None, fscope)\n",
            "ValueError: in user code:\n",
            "\n",
            "    File \"/usr/local/lib/python3.8/dist-packages/keras/engine/training.py\", line 1249, in train_function  *\n",
            "        return step_function(self, iterator)\n",
            "    File \"/usr/local/lib/python3.8/dist-packages/keras/engine/training.py\", line 1233, in step_function  **\n",
            "        outputs = model.distribute_strategy.run(run_step, args=(data,))\n",
            "    File \"/usr/local/lib/python3.8/dist-packages/keras/engine/training.py\", line 1222, in run_step  **\n",
            "        outputs = model.train_step(data)\n",
            "    File \"/usr/local/lib/python3.8/dist-packages/keras/engine/training.py\", line 1023, in train_step\n",
            "        y_pred = self(x, training=True)\n",
            "    File \"/usr/local/lib/python3.8/dist-packages/keras/utils/traceback_utils.py\", line 70, in error_handler\n",
            "        raise e.with_traceback(filtered_tb) from None\n",
            "    File \"/usr/local/lib/python3.8/dist-packages/keras/engine/input_spec.py\", line 295, in assert_input_compatibility\n",
            "        raise ValueError(\n",
            "\n",
            "    ValueError: Input 0 of layer \"sequential\" is incompatible with the layer: expected shape=(None, 20, 1), found shape=(None, 10, 1)\n",
            "\n",
            "\n",
            "--------------------------------------------------------------------------------\n",
            "1 fits failed with the following error:\n",
            "Traceback (most recent call last):\n",
            "  File \"/usr/local/lib/python3.8/dist-packages/sklearn/model_selection/_validation.py\", line 680, in _fit_and_score\n",
            "    estimator.fit(X_train, y_train, **fit_params)\n",
            "  File \"/usr/local/lib/python3.8/dist-packages/keras/wrappers/scikit_learn.py\", line 175, in fit\n",
            "    history = self.model.fit(x, y, **fit_args)\n",
            "  File \"/usr/local/lib/python3.8/dist-packages/keras/utils/traceback_utils.py\", line 70, in error_handler\n",
            "    raise e.with_traceback(filtered_tb) from None\n",
            "  File \"/tmp/__autograph_generated_filefstsicun.py\", line 15, in tf__train_function\n",
            "    retval_ = ag__.converted_call(ag__.ld(step_function), (ag__.ld(self), ag__.ld(iterator)), None, fscope)\n",
            "ValueError: in user code:\n",
            "\n",
            "    File \"/usr/local/lib/python3.8/dist-packages/keras/engine/training.py\", line 1249, in train_function  *\n",
            "        return step_function(self, iterator)\n",
            "    File \"/usr/local/lib/python3.8/dist-packages/keras/engine/training.py\", line 1233, in step_function  **\n",
            "        outputs = model.distribute_strategy.run(run_step, args=(data,))\n",
            "    File \"/usr/local/lib/python3.8/dist-packages/keras/engine/training.py\", line 1222, in run_step  **\n",
            "        outputs = model.train_step(data)\n",
            "    File \"/usr/local/lib/python3.8/dist-packages/keras/engine/training.py\", line 1023, in train_step\n",
            "        y_pred = self(x, training=True)\n",
            "    File \"/usr/local/lib/python3.8/dist-packages/keras/utils/traceback_utils.py\", line 70, in error_handler\n",
            "        raise e.with_traceback(filtered_tb) from None\n",
            "    File \"/usr/local/lib/python3.8/dist-packages/keras/engine/input_spec.py\", line 295, in assert_input_compatibility\n",
            "        raise ValueError(\n",
            "\n",
            "    ValueError: Input 0 of layer \"sequential_1\" is incompatible with the layer: expected shape=(None, 20, 1), found shape=(None, 10, 1)\n",
            "\n",
            "\n",
            "--------------------------------------------------------------------------------\n",
            "1 fits failed with the following error:\n",
            "Traceback (most recent call last):\n",
            "  File \"/usr/local/lib/python3.8/dist-packages/sklearn/model_selection/_validation.py\", line 680, in _fit_and_score\n",
            "    estimator.fit(X_train, y_train, **fit_params)\n",
            "  File \"/usr/local/lib/python3.8/dist-packages/keras/wrappers/scikit_learn.py\", line 175, in fit\n",
            "    history = self.model.fit(x, y, **fit_args)\n",
            "  File \"/usr/local/lib/python3.8/dist-packages/keras/utils/traceback_utils.py\", line 70, in error_handler\n",
            "    raise e.with_traceback(filtered_tb) from None\n",
            "  File \"/tmp/__autograph_generated_filefstsicun.py\", line 15, in tf__train_function\n",
            "    retval_ = ag__.converted_call(ag__.ld(step_function), (ag__.ld(self), ag__.ld(iterator)), None, fscope)\n",
            "ValueError: in user code:\n",
            "\n",
            "    File \"/usr/local/lib/python3.8/dist-packages/keras/engine/training.py\", line 1249, in train_function  *\n",
            "        return step_function(self, iterator)\n",
            "    File \"/usr/local/lib/python3.8/dist-packages/keras/engine/training.py\", line 1233, in step_function  **\n",
            "        outputs = model.distribute_strategy.run(run_step, args=(data,))\n",
            "    File \"/usr/local/lib/python3.8/dist-packages/keras/engine/training.py\", line 1222, in run_step  **\n",
            "        outputs = model.train_step(data)\n",
            "    File \"/usr/local/lib/python3.8/dist-packages/keras/engine/training.py\", line 1023, in train_step\n",
            "        y_pred = self(x, training=True)\n",
            "    File \"/usr/local/lib/python3.8/dist-packages/keras/utils/traceback_utils.py\", line 70, in error_handler\n",
            "        raise e.with_traceback(filtered_tb) from None\n",
            "    File \"/usr/local/lib/python3.8/dist-packages/keras/engine/input_spec.py\", line 295, in assert_input_compatibility\n",
            "        raise ValueError(\n",
            "\n",
            "    ValueError: Input 0 of layer \"sequential_2\" is incompatible with the layer: expected shape=(None, 20, 1), found shape=(None, 10, 1)\n",
            "\n",
            "\n",
            "--------------------------------------------------------------------------------\n",
            "1 fits failed with the following error:\n",
            "Traceback (most recent call last):\n",
            "  File \"/usr/local/lib/python3.8/dist-packages/sklearn/model_selection/_validation.py\", line 680, in _fit_and_score\n",
            "    estimator.fit(X_train, y_train, **fit_params)\n",
            "  File \"/usr/local/lib/python3.8/dist-packages/keras/wrappers/scikit_learn.py\", line 175, in fit\n",
            "    history = self.model.fit(x, y, **fit_args)\n",
            "  File \"/usr/local/lib/python3.8/dist-packages/keras/utils/traceback_utils.py\", line 70, in error_handler\n",
            "    raise e.with_traceback(filtered_tb) from None\n",
            "  File \"/tmp/__autograph_generated_filefstsicun.py\", line 15, in tf__train_function\n",
            "    retval_ = ag__.converted_call(ag__.ld(step_function), (ag__.ld(self), ag__.ld(iterator)), None, fscope)\n",
            "ValueError: in user code:\n",
            "\n",
            "    File \"/usr/local/lib/python3.8/dist-packages/keras/engine/training.py\", line 1249, in train_function  *\n",
            "        return step_function(self, iterator)\n",
            "    File \"/usr/local/lib/python3.8/dist-packages/keras/engine/training.py\", line 1233, in step_function  **\n",
            "        outputs = model.distribute_strategy.run(run_step, args=(data,))\n",
            "    File \"/usr/local/lib/python3.8/dist-packages/keras/engine/training.py\", line 1222, in run_step  **\n",
            "        outputs = model.train_step(data)\n",
            "    File \"/usr/local/lib/python3.8/dist-packages/keras/engine/training.py\", line 1023, in train_step\n",
            "        y_pred = self(x, training=True)\n",
            "    File \"/usr/local/lib/python3.8/dist-packages/keras/utils/traceback_utils.py\", line 70, in error_handler\n",
            "        raise e.with_traceback(filtered_tb) from None\n",
            "    File \"/usr/local/lib/python3.8/dist-packages/keras/engine/input_spec.py\", line 295, in assert_input_compatibility\n",
            "        raise ValueError(\n",
            "\n",
            "    ValueError: Input 0 of layer \"sequential_3\" is incompatible with the layer: expected shape=(None, 5, 1), found shape=(None, 10, 1)\n",
            "\n",
            "\n",
            "--------------------------------------------------------------------------------\n",
            "1 fits failed with the following error:\n",
            "Traceback (most recent call last):\n",
            "  File \"/usr/local/lib/python3.8/dist-packages/sklearn/model_selection/_validation.py\", line 680, in _fit_and_score\n",
            "    estimator.fit(X_train, y_train, **fit_params)\n",
            "  File \"/usr/local/lib/python3.8/dist-packages/keras/wrappers/scikit_learn.py\", line 175, in fit\n",
            "    history = self.model.fit(x, y, **fit_args)\n",
            "  File \"/usr/local/lib/python3.8/dist-packages/keras/utils/traceback_utils.py\", line 70, in error_handler\n",
            "    raise e.with_traceback(filtered_tb) from None\n",
            "  File \"/tmp/__autograph_generated_filefstsicun.py\", line 15, in tf__train_function\n",
            "    retval_ = ag__.converted_call(ag__.ld(step_function), (ag__.ld(self), ag__.ld(iterator)), None, fscope)\n",
            "ValueError: in user code:\n",
            "\n",
            "    File \"/usr/local/lib/python3.8/dist-packages/keras/engine/training.py\", line 1249, in train_function  *\n",
            "        return step_function(self, iterator)\n",
            "    File \"/usr/local/lib/python3.8/dist-packages/keras/engine/training.py\", line 1233, in step_function  **\n",
            "        outputs = model.distribute_strategy.run(run_step, args=(data,))\n",
            "    File \"/usr/local/lib/python3.8/dist-packages/keras/engine/training.py\", line 1222, in run_step  **\n",
            "        outputs = model.train_step(data)\n",
            "    File \"/usr/local/lib/python3.8/dist-packages/keras/engine/training.py\", line 1023, in train_step\n",
            "        y_pred = self(x, training=True)\n",
            "    File \"/usr/local/lib/python3.8/dist-packages/keras/utils/traceback_utils.py\", line 70, in error_handler\n",
            "        raise e.with_traceback(filtered_tb) from None\n",
            "    File \"/usr/local/lib/python3.8/dist-packages/keras/engine/input_spec.py\", line 295, in assert_input_compatibility\n",
            "        raise ValueError(\n",
            "\n",
            "    ValueError: Input 0 of layer \"sequential_4\" is incompatible with the layer: expected shape=(None, 5, 1), found shape=(None, 10, 1)\n",
            "\n",
            "\n",
            "--------------------------------------------------------------------------------\n",
            "1 fits failed with the following error:\n",
            "Traceback (most recent call last):\n",
            "  File \"/usr/local/lib/python3.8/dist-packages/sklearn/model_selection/_validation.py\", line 680, in _fit_and_score\n",
            "    estimator.fit(X_train, y_train, **fit_params)\n",
            "  File \"/usr/local/lib/python3.8/dist-packages/keras/wrappers/scikit_learn.py\", line 175, in fit\n",
            "    history = self.model.fit(x, y, **fit_args)\n",
            "  File \"/usr/local/lib/python3.8/dist-packages/keras/utils/traceback_utils.py\", line 70, in error_handler\n",
            "    raise e.with_traceback(filtered_tb) from None\n",
            "  File \"/tmp/__autograph_generated_filefstsicun.py\", line 15, in tf__train_function\n",
            "    retval_ = ag__.converted_call(ag__.ld(step_function), (ag__.ld(self), ag__.ld(iterator)), None, fscope)\n",
            "ValueError: in user code:\n",
            "\n",
            "    File \"/usr/local/lib/python3.8/dist-packages/keras/engine/training.py\", line 1249, in train_function  *\n",
            "        return step_function(self, iterator)\n",
            "    File \"/usr/local/lib/python3.8/dist-packages/keras/engine/training.py\", line 1233, in step_function  **\n",
            "        outputs = model.distribute_strategy.run(run_step, args=(data,))\n",
            "    File \"/usr/local/lib/python3.8/dist-packages/keras/engine/training.py\", line 1222, in run_step  **\n",
            "        outputs = model.train_step(data)\n",
            "    File \"/usr/local/lib/python3.8/dist-packages/keras/engine/training.py\", line 1023, in train_step\n",
            "        y_pred = self(x, training=True)\n",
            "    File \"/usr/local/lib/python3.8/dist-packages/keras/utils/traceback_utils.py\", line 70, in error_handler\n",
            "        raise e.with_traceback(filtered_tb) from None\n",
            "    File \"/usr/local/lib/python3.8/dist-packages/keras/engine/input_spec.py\", line 295, in assert_input_compatibility\n",
            "        raise ValueError(\n",
            "\n",
            "    ValueError: Input 0 of layer \"sequential_5\" is incompatible with the layer: expected shape=(None, 5, 1), found shape=(None, 10, 1)\n",
            "\n",
            "\n",
            "--------------------------------------------------------------------------------\n",
            "1 fits failed with the following error:\n",
            "Traceback (most recent call last):\n",
            "  File \"/usr/local/lib/python3.8/dist-packages/sklearn/model_selection/_validation.py\", line 680, in _fit_and_score\n",
            "    estimator.fit(X_train, y_train, **fit_params)\n",
            "  File \"/usr/local/lib/python3.8/dist-packages/keras/wrappers/scikit_learn.py\", line 175, in fit\n",
            "    history = self.model.fit(x, y, **fit_args)\n",
            "  File \"/usr/local/lib/python3.8/dist-packages/keras/utils/traceback_utils.py\", line 70, in error_handler\n",
            "    raise e.with_traceback(filtered_tb) from None\n",
            "  File \"/tmp/__autograph_generated_filet0wr41mh.py\", line 15, in tf__train_function\n",
            "    retval_ = ag__.converted_call(ag__.ld(step_function), (ag__.ld(self), ag__.ld(iterator)), None, fscope)\n",
            "ValueError: in user code:\n",
            "\n",
            "    File \"/usr/local/lib/python3.8/dist-packages/keras/engine/training.py\", line 1249, in train_function  *\n",
            "        return step_function(self, iterator)\n",
            "    File \"/usr/local/lib/python3.8/dist-packages/keras/engine/training.py\", line 1233, in step_function  **\n",
            "        outputs = model.distribute_strategy.run(run_step, args=(data,))\n",
            "    File \"/usr/local/lib/python3.8/dist-packages/keras/engine/training.py\", line 1222, in run_step  **\n",
            "        outputs = model.train_step(data)\n",
            "    File \"/usr/local/lib/python3.8/dist-packages/keras/engine/training.py\", line 1023, in train_step\n",
            "        y_pred = self(x, training=True)\n",
            "    File \"/usr/local/lib/python3.8/dist-packages/keras/utils/traceback_utils.py\", line 70, in error_handler\n",
            "        raise e.with_traceback(filtered_tb) from None\n",
            "    File \"/usr/local/lib/python3.8/dist-packages/keras/engine/input_spec.py\", line 295, in assert_input_compatibility\n",
            "        raise ValueError(\n",
            "\n",
            "    ValueError: Input 0 of layer \"sequential\" is incompatible with the layer: expected shape=(None, 20, 1), found shape=(None, 10, 1)\n",
            "\n",
            "\n",
            "--------------------------------------------------------------------------------\n",
            "1 fits failed with the following error:\n",
            "Traceback (most recent call last):\n",
            "  File \"/usr/local/lib/python3.8/dist-packages/sklearn/model_selection/_validation.py\", line 680, in _fit_and_score\n",
            "    estimator.fit(X_train, y_train, **fit_params)\n",
            "  File \"/usr/local/lib/python3.8/dist-packages/keras/wrappers/scikit_learn.py\", line 175, in fit\n",
            "    history = self.model.fit(x, y, **fit_args)\n",
            "  File \"/usr/local/lib/python3.8/dist-packages/keras/utils/traceback_utils.py\", line 70, in error_handler\n",
            "    raise e.with_traceback(filtered_tb) from None\n",
            "  File \"/tmp/__autograph_generated_filet0wr41mh.py\", line 15, in tf__train_function\n",
            "    retval_ = ag__.converted_call(ag__.ld(step_function), (ag__.ld(self), ag__.ld(iterator)), None, fscope)\n",
            "ValueError: in user code:\n",
            "\n",
            "    File \"/usr/local/lib/python3.8/dist-packages/keras/engine/training.py\", line 1249, in train_function  *\n",
            "        return step_function(self, iterator)\n",
            "    File \"/usr/local/lib/python3.8/dist-packages/keras/engine/training.py\", line 1233, in step_function  **\n",
            "        outputs = model.distribute_strategy.run(run_step, args=(data,))\n",
            "    File \"/usr/local/lib/python3.8/dist-packages/keras/engine/training.py\", line 1222, in run_step  **\n",
            "        outputs = model.train_step(data)\n",
            "    File \"/usr/local/lib/python3.8/dist-packages/keras/engine/training.py\", line 1023, in train_step\n",
            "        y_pred = self(x, training=True)\n",
            "    File \"/usr/local/lib/python3.8/dist-packages/keras/utils/traceback_utils.py\", line 70, in error_handler\n",
            "        raise e.with_traceback(filtered_tb) from None\n",
            "    File \"/usr/local/lib/python3.8/dist-packages/keras/engine/input_spec.py\", line 295, in assert_input_compatibility\n",
            "        raise ValueError(\n",
            "\n",
            "    ValueError: Input 0 of layer \"sequential_1\" is incompatible with the layer: expected shape=(None, 20, 1), found shape=(None, 10, 1)\n",
            "\n",
            "\n",
            "--------------------------------------------------------------------------------\n",
            "1 fits failed with the following error:\n",
            "Traceback (most recent call last):\n",
            "  File \"/usr/local/lib/python3.8/dist-packages/sklearn/model_selection/_validation.py\", line 680, in _fit_and_score\n",
            "    estimator.fit(X_train, y_train, **fit_params)\n",
            "  File \"/usr/local/lib/python3.8/dist-packages/keras/wrappers/scikit_learn.py\", line 175, in fit\n",
            "    history = self.model.fit(x, y, **fit_args)\n",
            "  File \"/usr/local/lib/python3.8/dist-packages/keras/utils/traceback_utils.py\", line 70, in error_handler\n",
            "    raise e.with_traceback(filtered_tb) from None\n",
            "  File \"/tmp/__autograph_generated_filet0wr41mh.py\", line 15, in tf__train_function\n",
            "    retval_ = ag__.converted_call(ag__.ld(step_function), (ag__.ld(self), ag__.ld(iterator)), None, fscope)\n",
            "ValueError: in user code:\n",
            "\n",
            "    File \"/usr/local/lib/python3.8/dist-packages/keras/engine/training.py\", line 1249, in train_function  *\n",
            "        return step_function(self, iterator)\n",
            "    File \"/usr/local/lib/python3.8/dist-packages/keras/engine/training.py\", line 1233, in step_function  **\n",
            "        outputs = model.distribute_strategy.run(run_step, args=(data,))\n",
            "    File \"/usr/local/lib/python3.8/dist-packages/keras/engine/training.py\", line 1222, in run_step  **\n",
            "        outputs = model.train_step(data)\n",
            "    File \"/usr/local/lib/python3.8/dist-packages/keras/engine/training.py\", line 1023, in train_step\n",
            "        y_pred = self(x, training=True)\n",
            "    File \"/usr/local/lib/python3.8/dist-packages/keras/utils/traceback_utils.py\", line 70, in error_handler\n",
            "        raise e.with_traceback(filtered_tb) from None\n",
            "    File \"/usr/local/lib/python3.8/dist-packages/keras/engine/input_spec.py\", line 295, in assert_input_compatibility\n",
            "        raise ValueError(\n",
            "\n",
            "    ValueError: Input 0 of layer \"sequential_2\" is incompatible with the layer: expected shape=(None, 20, 1), found shape=(None, 10, 1)\n",
            "\n",
            "\n",
            "--------------------------------------------------------------------------------\n",
            "1 fits failed with the following error:\n",
            "Traceback (most recent call last):\n",
            "  File \"/usr/local/lib/python3.8/dist-packages/sklearn/model_selection/_validation.py\", line 680, in _fit_and_score\n",
            "    estimator.fit(X_train, y_train, **fit_params)\n",
            "  File \"/usr/local/lib/python3.8/dist-packages/keras/wrappers/scikit_learn.py\", line 175, in fit\n",
            "    history = self.model.fit(x, y, **fit_args)\n",
            "  File \"/usr/local/lib/python3.8/dist-packages/keras/utils/traceback_utils.py\", line 70, in error_handler\n",
            "    raise e.with_traceback(filtered_tb) from None\n",
            "  File \"/tmp/__autograph_generated_filet0wr41mh.py\", line 15, in tf__train_function\n",
            "    retval_ = ag__.converted_call(ag__.ld(step_function), (ag__.ld(self), ag__.ld(iterator)), None, fscope)\n",
            "ValueError: in user code:\n",
            "\n",
            "    File \"/usr/local/lib/python3.8/dist-packages/keras/engine/training.py\", line 1249, in train_function  *\n",
            "        return step_function(self, iterator)\n",
            "    File \"/usr/local/lib/python3.8/dist-packages/keras/engine/training.py\", line 1233, in step_function  **\n",
            "        outputs = model.distribute_strategy.run(run_step, args=(data,))\n",
            "    File \"/usr/local/lib/python3.8/dist-packages/keras/engine/training.py\", line 1222, in run_step  **\n",
            "        outputs = model.train_step(data)\n",
            "    File \"/usr/local/lib/python3.8/dist-packages/keras/engine/training.py\", line 1023, in train_step\n",
            "        y_pred = self(x, training=True)\n",
            "    File \"/usr/local/lib/python3.8/dist-packages/keras/utils/traceback_utils.py\", line 70, in error_handler\n",
            "        raise e.with_traceback(filtered_tb) from None\n",
            "    File \"/usr/local/lib/python3.8/dist-packages/keras/engine/input_spec.py\", line 295, in assert_input_compatibility\n",
            "        raise ValueError(\n",
            "\n",
            "    ValueError: Input 0 of layer \"sequential_3\" is incompatible with the layer: expected shape=(None, 5, 1), found shape=(None, 10, 1)\n",
            "\n",
            "\n",
            "--------------------------------------------------------------------------------\n",
            "1 fits failed with the following error:\n",
            "Traceback (most recent call last):\n",
            "  File \"/usr/local/lib/python3.8/dist-packages/sklearn/model_selection/_validation.py\", line 680, in _fit_and_score\n",
            "    estimator.fit(X_train, y_train, **fit_params)\n",
            "  File \"/usr/local/lib/python3.8/dist-packages/keras/wrappers/scikit_learn.py\", line 175, in fit\n",
            "    history = self.model.fit(x, y, **fit_args)\n",
            "  File \"/usr/local/lib/python3.8/dist-packages/keras/utils/traceback_utils.py\", line 70, in error_handler\n",
            "    raise e.with_traceback(filtered_tb) from None\n",
            "  File \"/tmp/__autograph_generated_filet0wr41mh.py\", line 15, in tf__train_function\n",
            "    retval_ = ag__.converted_call(ag__.ld(step_function), (ag__.ld(self), ag__.ld(iterator)), None, fscope)\n",
            "ValueError: in user code:\n",
            "\n",
            "    File \"/usr/local/lib/python3.8/dist-packages/keras/engine/training.py\", line 1249, in train_function  *\n",
            "        return step_function(self, iterator)\n",
            "    File \"/usr/local/lib/python3.8/dist-packages/keras/engine/training.py\", line 1233, in step_function  **\n",
            "        outputs = model.distribute_strategy.run(run_step, args=(data,))\n",
            "    File \"/usr/local/lib/python3.8/dist-packages/keras/engine/training.py\", line 1222, in run_step  **\n",
            "        outputs = model.train_step(data)\n",
            "    File \"/usr/local/lib/python3.8/dist-packages/keras/engine/training.py\", line 1023, in train_step\n",
            "        y_pred = self(x, training=True)\n",
            "    File \"/usr/local/lib/python3.8/dist-packages/keras/utils/traceback_utils.py\", line 70, in error_handler\n",
            "        raise e.with_traceback(filtered_tb) from None\n",
            "    File \"/usr/local/lib/python3.8/dist-packages/keras/engine/input_spec.py\", line 295, in assert_input_compatibility\n",
            "        raise ValueError(\n",
            "\n",
            "    ValueError: Input 0 of layer \"sequential_4\" is incompatible with the layer: expected shape=(None, 5, 1), found shape=(None, 10, 1)\n",
            "\n",
            "\n",
            "--------------------------------------------------------------------------------\n",
            "1 fits failed with the following error:\n",
            "Traceback (most recent call last):\n",
            "  File \"/usr/local/lib/python3.8/dist-packages/sklearn/model_selection/_validation.py\", line 680, in _fit_and_score\n",
            "    estimator.fit(X_train, y_train, **fit_params)\n",
            "  File \"/usr/local/lib/python3.8/dist-packages/keras/wrappers/scikit_learn.py\", line 175, in fit\n",
            "    history = self.model.fit(x, y, **fit_args)\n",
            "  File \"/usr/local/lib/python3.8/dist-packages/keras/utils/traceback_utils.py\", line 70, in error_handler\n",
            "    raise e.with_traceback(filtered_tb) from None\n",
            "  File \"/tmp/__autograph_generated_filet0wr41mh.py\", line 15, in tf__train_function\n",
            "    retval_ = ag__.converted_call(ag__.ld(step_function), (ag__.ld(self), ag__.ld(iterator)), None, fscope)\n",
            "ValueError: in user code:\n",
            "\n",
            "    File \"/usr/local/lib/python3.8/dist-packages/keras/engine/training.py\", line 1249, in train_function  *\n",
            "        return step_function(self, iterator)\n",
            "    File \"/usr/local/lib/python3.8/dist-packages/keras/engine/training.py\", line 1233, in step_function  **\n",
            "        outputs = model.distribute_strategy.run(run_step, args=(data,))\n",
            "    File \"/usr/local/lib/python3.8/dist-packages/keras/engine/training.py\", line 1222, in run_step  **\n",
            "        outputs = model.train_step(data)\n",
            "    File \"/usr/local/lib/python3.8/dist-packages/keras/engine/training.py\", line 1023, in train_step\n",
            "        y_pred = self(x, training=True)\n",
            "    File \"/usr/local/lib/python3.8/dist-packages/keras/utils/traceback_utils.py\", line 70, in error_handler\n",
            "        raise e.with_traceback(filtered_tb) from None\n",
            "    File \"/usr/local/lib/python3.8/dist-packages/keras/engine/input_spec.py\", line 295, in assert_input_compatibility\n",
            "        raise ValueError(\n",
            "\n",
            "    ValueError: Input 0 of layer \"sequential_5\" is incompatible with the layer: expected shape=(None, 5, 1), found shape=(None, 10, 1)\n",
            "\n",
            "\n",
            "--------------------------------------------------------------------------------\n",
            "1 fits failed with the following error:\n",
            "Traceback (most recent call last):\n",
            "  File \"/usr/local/lib/python3.8/dist-packages/sklearn/model_selection/_validation.py\", line 680, in _fit_and_score\n",
            "    estimator.fit(X_train, y_train, **fit_params)\n",
            "  File \"/usr/local/lib/python3.8/dist-packages/keras/wrappers/scikit_learn.py\", line 175, in fit\n",
            "    history = self.model.fit(x, y, **fit_args)\n",
            "  File \"/usr/local/lib/python3.8/dist-packages/keras/utils/traceback_utils.py\", line 70, in error_handler\n",
            "    raise e.with_traceback(filtered_tb) from None\n",
            "  File \"/tmp/__autograph_generated_filez7n9i83q.py\", line 15, in tf__train_function\n",
            "    retval_ = ag__.converted_call(ag__.ld(step_function), (ag__.ld(self), ag__.ld(iterator)), None, fscope)\n",
            "ValueError: in user code:\n",
            "\n",
            "    File \"/usr/local/lib/python3.8/dist-packages/keras/engine/training.py\", line 1249, in train_function  *\n",
            "        return step_function(self, iterator)\n",
            "    File \"/usr/local/lib/python3.8/dist-packages/keras/engine/training.py\", line 1233, in step_function  **\n",
            "        outputs = model.distribute_strategy.run(run_step, args=(data,))\n",
            "    File \"/usr/local/lib/python3.8/dist-packages/keras/engine/training.py\", line 1222, in run_step  **\n",
            "        outputs = model.train_step(data)\n",
            "    File \"/usr/local/lib/python3.8/dist-packages/keras/engine/training.py\", line 1023, in train_step\n",
            "        y_pred = self(x, training=True)\n",
            "    File \"/usr/local/lib/python3.8/dist-packages/keras/utils/traceback_utils.py\", line 70, in error_handler\n",
            "        raise e.with_traceback(filtered_tb) from None\n",
            "    File \"/usr/local/lib/python3.8/dist-packages/keras/engine/input_spec.py\", line 295, in assert_input_compatibility\n",
            "        raise ValueError(\n",
            "\n",
            "    ValueError: Input 0 of layer \"sequential_3\" is incompatible with the layer: expected shape=(None, 20, 1), found shape=(None, 10, 1)\n",
            "\n",
            "\n",
            "--------------------------------------------------------------------------------\n",
            "1 fits failed with the following error:\n",
            "Traceback (most recent call last):\n",
            "  File \"/usr/local/lib/python3.8/dist-packages/sklearn/model_selection/_validation.py\", line 680, in _fit_and_score\n",
            "    estimator.fit(X_train, y_train, **fit_params)\n",
            "  File \"/usr/local/lib/python3.8/dist-packages/keras/wrappers/scikit_learn.py\", line 175, in fit\n",
            "    history = self.model.fit(x, y, **fit_args)\n",
            "  File \"/usr/local/lib/python3.8/dist-packages/keras/utils/traceback_utils.py\", line 70, in error_handler\n",
            "    raise e.with_traceback(filtered_tb) from None\n",
            "  File \"/tmp/__autograph_generated_filez7n9i83q.py\", line 15, in tf__train_function\n",
            "    retval_ = ag__.converted_call(ag__.ld(step_function), (ag__.ld(self), ag__.ld(iterator)), None, fscope)\n",
            "ValueError: in user code:\n",
            "\n",
            "    File \"/usr/local/lib/python3.8/dist-packages/keras/engine/training.py\", line 1249, in train_function  *\n",
            "        return step_function(self, iterator)\n",
            "    File \"/usr/local/lib/python3.8/dist-packages/keras/engine/training.py\", line 1233, in step_function  **\n",
            "        outputs = model.distribute_strategy.run(run_step, args=(data,))\n",
            "    File \"/usr/local/lib/python3.8/dist-packages/keras/engine/training.py\", line 1222, in run_step  **\n",
            "        outputs = model.train_step(data)\n",
            "    File \"/usr/local/lib/python3.8/dist-packages/keras/engine/training.py\", line 1023, in train_step\n",
            "        y_pred = self(x, training=True)\n",
            "    File \"/usr/local/lib/python3.8/dist-packages/keras/utils/traceback_utils.py\", line 70, in error_handler\n",
            "        raise e.with_traceback(filtered_tb) from None\n",
            "    File \"/usr/local/lib/python3.8/dist-packages/keras/engine/input_spec.py\", line 295, in assert_input_compatibility\n",
            "        raise ValueError(\n",
            "\n",
            "    ValueError: Input 0 of layer \"sequential_4\" is incompatible with the layer: expected shape=(None, 20, 1), found shape=(None, 10, 1)\n",
            "\n",
            "\n",
            "--------------------------------------------------------------------------------\n",
            "1 fits failed with the following error:\n",
            "Traceback (most recent call last):\n",
            "  File \"/usr/local/lib/python3.8/dist-packages/sklearn/model_selection/_validation.py\", line 680, in _fit_and_score\n",
            "    estimator.fit(X_train, y_train, **fit_params)\n",
            "  File \"/usr/local/lib/python3.8/dist-packages/keras/wrappers/scikit_learn.py\", line 175, in fit\n",
            "    history = self.model.fit(x, y, **fit_args)\n",
            "  File \"/usr/local/lib/python3.8/dist-packages/keras/utils/traceback_utils.py\", line 70, in error_handler\n",
            "    raise e.with_traceback(filtered_tb) from None\n",
            "  File \"/tmp/__autograph_generated_filez7n9i83q.py\", line 15, in tf__train_function\n",
            "    retval_ = ag__.converted_call(ag__.ld(step_function), (ag__.ld(self), ag__.ld(iterator)), None, fscope)\n",
            "ValueError: in user code:\n",
            "\n",
            "    File \"/usr/local/lib/python3.8/dist-packages/keras/engine/training.py\", line 1249, in train_function  *\n",
            "        return step_function(self, iterator)\n",
            "    File \"/usr/local/lib/python3.8/dist-packages/keras/engine/training.py\", line 1233, in step_function  **\n",
            "        outputs = model.distribute_strategy.run(run_step, args=(data,))\n",
            "    File \"/usr/local/lib/python3.8/dist-packages/keras/engine/training.py\", line 1222, in run_step  **\n",
            "        outputs = model.train_step(data)\n",
            "    File \"/usr/local/lib/python3.8/dist-packages/keras/engine/training.py\", line 1023, in train_step\n",
            "        y_pred = self(x, training=True)\n",
            "    File \"/usr/local/lib/python3.8/dist-packages/keras/utils/traceback_utils.py\", line 70, in error_handler\n",
            "        raise e.with_traceback(filtered_tb) from None\n",
            "    File \"/usr/local/lib/python3.8/dist-packages/keras/engine/input_spec.py\", line 295, in assert_input_compatibility\n",
            "        raise ValueError(\n",
            "\n",
            "    ValueError: Input 0 of layer \"sequential_5\" is incompatible with the layer: expected shape=(None, 20, 1), found shape=(None, 10, 1)\n",
            "\n",
            "\n",
            "  warnings.warn(some_fits_failed_message, FitFailedWarning)\n",
            "/usr/local/lib/python3.8/dist-packages/sklearn/model_selection/_search.py:969: UserWarning: One or more of the test scores are non-finite: [        nan -0.52223233         nan         nan -0.52105878         nan\n",
            "         nan -0.51981777         nan         nan -0.52145571         nan\n",
            "         nan -0.52401499         nan         nan -0.52447667         nan]\n",
            "  warnings.warn(\n"
          ]
        },
        {
          "output_type": "stream",
          "name": "stdout",
          "text": [
            "Best: -0.519818 using {'batch_size': 20, 'epochs': 10, 'lag': 10}\n"
          ]
        }
      ]
    },
    {
      "cell_type": "code",
      "source": [
        "print(\"Best: %f using %s\" % (grid_result.best_score_, grid_result.best_params_))"
      ],
      "metadata": {
        "colab": {
          "base_uri": "https://localhost:8080/"
        },
        "id": "hEGobEbBP8uq",
        "outputId": "f1e40d6d-0a07-4ec3-b54e-42079f977105"
      },
      "execution_count": null,
      "outputs": [
        {
          "output_type": "stream",
          "name": "stdout",
          "text": [
            "Best: -0.519818 using {'batch_size': 20, 'epochs': 10, 'lag': 10}\n"
          ]
        }
      ]
    }
  ]
}